ERROR 2025-08-12 02:13:33,130 log 66648 71644 Internal Server Error: /api/projects/
Traceback (most recent call last):
  File "C:\Users\kongata.AMERIDUKA.000\Desktop\finance-tracker\backend\venv\Lib\site-packages\django\core\handlers\exception.py", line 55, in inner
    response = get_response(request)
  File "C:\Users\kongata.AMERIDUKA.000\Desktop\finance-tracker\backend\venv\Lib\site-packages\django\core\handlers\base.py", line 197, in _get_response
    response = wrapped_callback(request, *callback_args, **callback_kwargs)
  File "C:\Users\kongata.AMERIDUKA.000\Desktop\finance-tracker\backend\venv\Lib\site-packages\django\views\decorators\csrf.py", line 65, in _view_wrapper
    return view_func(request, *args, **kwargs)
  File "C:\Users\kongata.AMERIDUKA.000\Desktop\finance-tracker\backend\venv\Lib\site-packages\rest_framework\viewsets.py", line 125, in view
    return self.dispatch(request, *args, **kwargs)
           ~~~~~~~~~~~~~^^^^^^^^^^^^^^^^^^^^^^^^^^
  File "C:\Users\kongata.AMERIDUKA.000\Desktop\finance-tracker\backend\venv\Lib\site-packages\rest_framework\views.py", line 515, in dispatch
    response = self.handle_exception(exc)
  File "C:\Users\kongata.AMERIDUKA.000\Desktop\finance-tracker\backend\venv\Lib\site-packages\rest_framework\views.py", line 475, in handle_exception
    self.raise_uncaught_exception(exc)
    ~~~~~~~~~~~~~~~~~~~~~~~~~~~~~^^^^^
  File "C:\Users\kongata.AMERIDUKA.000\Desktop\finance-tracker\backend\venv\Lib\site-packages\rest_framework\views.py", line 486, in raise_uncaught_exception
    raise exc
  File "C:\Users\kongata.AMERIDUKA.000\Desktop\finance-tracker\backend\venv\Lib\site-packages\rest_framework\views.py", line 512, in dispatch
    response = handler(request, *args, **kwargs)
  File "C:\Users\kongata.AMERIDUKA.000\Desktop\finance-tracker\backend\venv\Lib\site-packages\rest_framework\mixins.py", line 40, in list
    page = self.paginate_queryset(queryset)
  File "C:\Users\kongata.AMERIDUKA.000\Desktop\finance-tracker\backend\venv\Lib\site-packages\rest_framework\generics.py", line 175, in paginate_queryset
    return self.paginator.paginate_queryset(queryset, self.request, view=self)
           ~~~~~~~~~~~~~~~~~~~~~~~~~~~~~~~~^^^^^^^^^^^^^^^^^^^^^^^^^^^^^^^^^^^
  File "C:\Users\kongata.AMERIDUKA.000\Desktop\finance-tracker\backend\venv\Lib\site-packages\rest_framework\pagination.py", line 222, in paginate_queryset
    return list(self.page)
  File "C:\Users\kongata.AMERIDUKA.000\Desktop\finance-tracker\backend\venv\Lib\site-packages\django\core\paginator.py", line 191, in __len__
    return len(self.object_list)
  File "C:\Users\kongata.AMERIDUKA.000\Desktop\finance-tracker\backend\venv\Lib\site-packages\django\db\models\query.py", line 366, in __len__
    self._fetch_all()
    ~~~~~~~~~~~~~~~^^
  File "C:\Users\kongata.AMERIDUKA.000\Desktop\finance-tracker\backend\venv\Lib\site-packages\django\db\models\query.py", line 1949, in _fetch_all
    self._result_cache = list(self._iterable_class(self))
                         ~~~~^^^^^^^^^^^^^^^^^^^^^^^^^^^^
  File "C:\Users\kongata.AMERIDUKA.000\Desktop\finance-tracker\backend\venv\Lib\site-packages\django\db\models\query.py", line 91, in __iter__
    results = compiler.execute_sql(
        chunked_fetch=self.chunked_fetch, chunk_size=self.chunk_size
    )
  File "C:\Users\kongata.AMERIDUKA.000\Desktop\finance-tracker\backend\venv\Lib\site-packages\django\db\models\sql\compiler.py", line 1610, in execute_sql
    sql, params = self.as_sql()
                  ~~~~~~~~~~~^^
  File "C:\Users\kongata.AMERIDUKA.000\Desktop\finance-tracker\backend\venv\Lib\site-packages\django\db\models\sql\compiler.py", line 766, in as_sql
    extra_select, order_by, group_by = self.pre_sql_setup(
                                       ~~~~~~~~~~~~~~~~~~^
        with_col_aliases=with_col_aliases or bool(combinator),
        ^^^^^^^^^^^^^^^^^^^^^^^^^^^^^^^^^^^^^^^^^^^^^^^^^^^^^^
    )
    ^
  File "C:\Users\kongata.AMERIDUKA.000\Desktop\finance-tracker\backend\venv\Lib\site-packages\django\db\models\sql\compiler.py", line 86, in pre_sql_setup
    order_by = self.get_order_by()
  File "C:\Users\kongata.AMERIDUKA.000\Desktop\finance-tracker\backend\venv\Lib\site-packages\django\db\models\sql\compiler.py", line 490, in get_order_by
    for expr, is_ref in self._order_by_pairs():
                        ~~~~~~~~~~~~~~~~~~~~^^
  File "C:\Users\kongata.AMERIDUKA.000\Desktop\finance-tracker\backend\venv\Lib\site-packages\django\db\models\sql\compiler.py", line 473, in _order_by_pairs
    yield from self.find_ordering_name(
               ~~~~~~~~~~~~~~~~~~~~~~~^
        field,
        ^^^^^^
        self.query.get_meta(),
        ^^^^^^^^^^^^^^^^^^^^^^
        default_order=default_order,
        ^^^^^^^^^^^^^^^^^^^^^^^^^^^^
    )
    ^
  File "C:\Users\kongata.AMERIDUKA.000\Desktop\finance-tracker\backend\venv\Lib\site-packages\django\db\models\sql\compiler.py", line 1113, in find_ordering_name
    for expr, is_ref in self.find_ordering_name(
                        ~~~~~~~~~~~~~~~~~~~~~~~^
        item, opts, alias, order, already_seen
        ^^^^^^^^^^^^^^^^^^^^^^^^^^^^^^^^^^^^^^
    )
    ^
  File "C:\Users\kongata.AMERIDUKA.000\Desktop\finance-tracker\backend\venv\Lib\site-packages\django\db\models\sql\compiler.py", line 1113, in find_ordering_name
    for expr, is_ref in self.find_ordering_name(
                        ~~~~~~~~~~~~~~~~~~~~~~~^
        item, opts, alias, order, already_seen
        ^^^^^^^^^^^^^^^^^^^^^^^^^^^^^^^^^^^^^^
    )
    ^
  File "C:\Users\kongata.AMERIDUKA.000\Desktop\finance-tracker\backend\venv\Lib\site-packages\django\db\models\sql\compiler.py", line 1097, in find_ordering_name
    raise FieldError("Infinite loop caused by ordering.")
django.core.exceptions.FieldError: Infinite loop caused by ordering.
ERROR 2025-08-12 02:13:33,137 basehttp 66648 71644 "GET /api/projects/ HTTP/1.1" 500 175082
ERROR 2025-08-12 02:13:33,167 log 66648 65692 Internal Server Error: /api/projects/
Traceback (most recent call last):
  File "C:\Users\kongata.AMERIDUKA.000\Desktop\finance-tracker\backend\venv\Lib\site-packages\django\core\handlers\exception.py", line 55, in inner
    response = get_response(request)
  File "C:\Users\kongata.AMERIDUKA.000\Desktop\finance-tracker\backend\venv\Lib\site-packages\django\core\handlers\base.py", line 197, in _get_response
    response = wrapped_callback(request, *callback_args, **callback_kwargs)
  File "C:\Users\kongata.AMERIDUKA.000\Desktop\finance-tracker\backend\venv\Lib\site-packages\django\views\decorators\csrf.py", line 65, in _view_wrapper
    return view_func(request, *args, **kwargs)
  File "C:\Users\kongata.AMERIDUKA.000\Desktop\finance-tracker\backend\venv\Lib\site-packages\rest_framework\viewsets.py", line 125, in view
    return self.dispatch(request, *args, **kwargs)
           ~~~~~~~~~~~~~^^^^^^^^^^^^^^^^^^^^^^^^^^
  File "C:\Users\kongata.AMERIDUKA.000\Desktop\finance-tracker\backend\venv\Lib\site-packages\rest_framework\views.py", line 515, in dispatch
    response = self.handle_exception(exc)
  File "C:\Users\kongata.AMERIDUKA.000\Desktop\finance-tracker\backend\venv\Lib\site-packages\rest_framework\views.py", line 475, in handle_exception
    self.raise_uncaught_exception(exc)
    ~~~~~~~~~~~~~~~~~~~~~~~~~~~~~^^^^^
  File "C:\Users\kongata.AMERIDUKA.000\Desktop\finance-tracker\backend\venv\Lib\site-packages\rest_framework\views.py", line 486, in raise_uncaught_exception
    raise exc
  File "C:\Users\kongata.AMERIDUKA.000\Desktop\finance-tracker\backend\venv\Lib\site-packages\rest_framework\views.py", line 512, in dispatch
    response = handler(request, *args, **kwargs)
  File "C:\Users\kongata.AMERIDUKA.000\Desktop\finance-tracker\backend\venv\Lib\site-packages\rest_framework\mixins.py", line 40, in list
    page = self.paginate_queryset(queryset)
  File "C:\Users\kongata.AMERIDUKA.000\Desktop\finance-tracker\backend\venv\Lib\site-packages\rest_framework\generics.py", line 175, in paginate_queryset
    return self.paginator.paginate_queryset(queryset, self.request, view=self)
           ~~~~~~~~~~~~~~~~~~~~~~~~~~~~~~~~^^^^^^^^^^^^^^^^^^^^^^^^^^^^^^^^^^^
  File "C:\Users\kongata.AMERIDUKA.000\Desktop\finance-tracker\backend\venv\Lib\site-packages\rest_framework\pagination.py", line 222, in paginate_queryset
    return list(self.page)
  File "C:\Users\kongata.AMERIDUKA.000\Desktop\finance-tracker\backend\venv\Lib\site-packages\django\core\paginator.py", line 191, in __len__
    return len(self.object_list)
  File "C:\Users\kongata.AMERIDUKA.000\Desktop\finance-tracker\backend\venv\Lib\site-packages\django\db\models\query.py", line 366, in __len__
    self._fetch_all()
    ~~~~~~~~~~~~~~~^^
  File "C:\Users\kongata.AMERIDUKA.000\Desktop\finance-tracker\backend\venv\Lib\site-packages\django\db\models\query.py", line 1949, in _fetch_all
    self._result_cache = list(self._iterable_class(self))
                         ~~~~^^^^^^^^^^^^^^^^^^^^^^^^^^^^
  File "C:\Users\kongata.AMERIDUKA.000\Desktop\finance-tracker\backend\venv\Lib\site-packages\django\db\models\query.py", line 91, in __iter__
    results = compiler.execute_sql(
        chunked_fetch=self.chunked_fetch, chunk_size=self.chunk_size
    )
  File "C:\Users\kongata.AMERIDUKA.000\Desktop\finance-tracker\backend\venv\Lib\site-packages\django\db\models\sql\compiler.py", line 1610, in execute_sql
    sql, params = self.as_sql()
                  ~~~~~~~~~~~^^
  File "C:\Users\kongata.AMERIDUKA.000\Desktop\finance-tracker\backend\venv\Lib\site-packages\django\db\models\sql\compiler.py", line 766, in as_sql
    extra_select, order_by, group_by = self.pre_sql_setup(
                                       ~~~~~~~~~~~~~~~~~~^
        with_col_aliases=with_col_aliases or bool(combinator),
        ^^^^^^^^^^^^^^^^^^^^^^^^^^^^^^^^^^^^^^^^^^^^^^^^^^^^^^
    )
    ^
  File "C:\Users\kongata.AMERIDUKA.000\Desktop\finance-tracker\backend\venv\Lib\site-packages\django\db\models\sql\compiler.py", line 86, in pre_sql_setup
    order_by = self.get_order_by()
  File "C:\Users\kongata.AMERIDUKA.000\Desktop\finance-tracker\backend\venv\Lib\site-packages\django\db\models\sql\compiler.py", line 490, in get_order_by
    for expr, is_ref in self._order_by_pairs():
                        ~~~~~~~~~~~~~~~~~~~~^^
  File "C:\Users\kongata.AMERIDUKA.000\Desktop\finance-tracker\backend\venv\Lib\site-packages\django\db\models\sql\compiler.py", line 473, in _order_by_pairs
    yield from self.find_ordering_name(
               ~~~~~~~~~~~~~~~~~~~~~~~^
        field,
        ^^^^^^
        self.query.get_meta(),
        ^^^^^^^^^^^^^^^^^^^^^^
        default_order=default_order,
        ^^^^^^^^^^^^^^^^^^^^^^^^^^^^
    )
    ^
  File "C:\Users\kongata.AMERIDUKA.000\Desktop\finance-tracker\backend\venv\Lib\site-packages\django\db\models\sql\compiler.py", line 1113, in find_ordering_name
    for expr, is_ref in self.find_ordering_name(
                        ~~~~~~~~~~~~~~~~~~~~~~~^
        item, opts, alias, order, already_seen
        ^^^^^^^^^^^^^^^^^^^^^^^^^^^^^^^^^^^^^^
    )
    ^
  File "C:\Users\kongata.AMERIDUKA.000\Desktop\finance-tracker\backend\venv\Lib\site-packages\django\db\models\sql\compiler.py", line 1113, in find_ordering_name
    for expr, is_ref in self.find_ordering_name(
                        ~~~~~~~~~~~~~~~~~~~~~~~^
        item, opts, alias, order, already_seen
        ^^^^^^^^^^^^^^^^^^^^^^^^^^^^^^^^^^^^^^
    )
    ^
  File "C:\Users\kongata.AMERIDUKA.000\Desktop\finance-tracker\backend\venv\Lib\site-packages\django\db\models\sql\compiler.py", line 1097, in find_ordering_name
    raise FieldError("Infinite loop caused by ordering.")
django.core.exceptions.FieldError: Infinite loop caused by ordering.
ERROR 2025-08-12 02:13:33,172 basehttp 66648 65692 "GET /api/projects/ HTTP/1.1" 500 175082
ERROR 2025-08-12 02:13:53,156 log 66648 71644 Internal Server Error: /api/projects/
Traceback (most recent call last):
  File "C:\Users\kongata.AMERIDUKA.000\Desktop\finance-tracker\backend\venv\Lib\site-packages\django\core\handlers\exception.py", line 55, in inner
    response = get_response(request)
  File "C:\Users\kongata.AMERIDUKA.000\Desktop\finance-tracker\backend\venv\Lib\site-packages\django\core\handlers\base.py", line 197, in _get_response
    response = wrapped_callback(request, *callback_args, **callback_kwargs)
  File "C:\Users\kongata.AMERIDUKA.000\Desktop\finance-tracker\backend\venv\Lib\site-packages\django\views\decorators\csrf.py", line 65, in _view_wrapper
    return view_func(request, *args, **kwargs)
  File "C:\Users\kongata.AMERIDUKA.000\Desktop\finance-tracker\backend\venv\Lib\site-packages\rest_framework\viewsets.py", line 125, in view
    return self.dispatch(request, *args, **kwargs)
           ~~~~~~~~~~~~~^^^^^^^^^^^^^^^^^^^^^^^^^^
  File "C:\Users\kongata.AMERIDUKA.000\Desktop\finance-tracker\backend\venv\Lib\site-packages\rest_framework\views.py", line 515, in dispatch
    response = self.handle_exception(exc)
  File "C:\Users\kongata.AMERIDUKA.000\Desktop\finance-tracker\backend\venv\Lib\site-packages\rest_framework\views.py", line 475, in handle_exception
    self.raise_uncaught_exception(exc)
    ~~~~~~~~~~~~~~~~~~~~~~~~~~~~~^^^^^
  File "C:\Users\kongata.AMERIDUKA.000\Desktop\finance-tracker\backend\venv\Lib\site-packages\rest_framework\views.py", line 486, in raise_uncaught_exception
    raise exc
  File "C:\Users\kongata.AMERIDUKA.000\Desktop\finance-tracker\backend\venv\Lib\site-packages\rest_framework\views.py", line 512, in dispatch
    response = handler(request, *args, **kwargs)
  File "C:\Users\kongata.AMERIDUKA.000\Desktop\finance-tracker\backend\venv\Lib\site-packages\rest_framework\mixins.py", line 40, in list
    page = self.paginate_queryset(queryset)
  File "C:\Users\kongata.AMERIDUKA.000\Desktop\finance-tracker\backend\venv\Lib\site-packages\rest_framework\generics.py", line 175, in paginate_queryset
    return self.paginator.paginate_queryset(queryset, self.request, view=self)
           ~~~~~~~~~~~~~~~~~~~~~~~~~~~~~~~~^^^^^^^^^^^^^^^^^^^^^^^^^^^^^^^^^^^
  File "C:\Users\kongata.AMERIDUKA.000\Desktop\finance-tracker\backend\venv\Lib\site-packages\rest_framework\pagination.py", line 222, in paginate_queryset
    return list(self.page)
  File "C:\Users\kongata.AMERIDUKA.000\Desktop\finance-tracker\backend\venv\Lib\site-packages\django\core\paginator.py", line 191, in __len__
    return len(self.object_list)
  File "C:\Users\kongata.AMERIDUKA.000\Desktop\finance-tracker\backend\venv\Lib\site-packages\django\db\models\query.py", line 366, in __len__
    self._fetch_all()
    ~~~~~~~~~~~~~~~^^
  File "C:\Users\kongata.AMERIDUKA.000\Desktop\finance-tracker\backend\venv\Lib\site-packages\django\db\models\query.py", line 1949, in _fetch_all
    self._result_cache = list(self._iterable_class(self))
                         ~~~~^^^^^^^^^^^^^^^^^^^^^^^^^^^^
  File "C:\Users\kongata.AMERIDUKA.000\Desktop\finance-tracker\backend\venv\Lib\site-packages\django\db\models\query.py", line 91, in __iter__
    results = compiler.execute_sql(
        chunked_fetch=self.chunked_fetch, chunk_size=self.chunk_size
    )
  File "C:\Users\kongata.AMERIDUKA.000\Desktop\finance-tracker\backend\venv\Lib\site-packages\django\db\models\sql\compiler.py", line 1610, in execute_sql
    sql, params = self.as_sql()
                  ~~~~~~~~~~~^^
  File "C:\Users\kongata.AMERIDUKA.000\Desktop\finance-tracker\backend\venv\Lib\site-packages\django\db\models\sql\compiler.py", line 766, in as_sql
    extra_select, order_by, group_by = self.pre_sql_setup(
                                       ~~~~~~~~~~~~~~~~~~^
        with_col_aliases=with_col_aliases or bool(combinator),
        ^^^^^^^^^^^^^^^^^^^^^^^^^^^^^^^^^^^^^^^^^^^^^^^^^^^^^^
    )
    ^
  File "C:\Users\kongata.AMERIDUKA.000\Desktop\finance-tracker\backend\venv\Lib\site-packages\django\db\models\sql\compiler.py", line 86, in pre_sql_setup
    order_by = self.get_order_by()
  File "C:\Users\kongata.AMERIDUKA.000\Desktop\finance-tracker\backend\venv\Lib\site-packages\django\db\models\sql\compiler.py", line 490, in get_order_by
    for expr, is_ref in self._order_by_pairs():
                        ~~~~~~~~~~~~~~~~~~~~^^
  File "C:\Users\kongata.AMERIDUKA.000\Desktop\finance-tracker\backend\venv\Lib\site-packages\django\db\models\sql\compiler.py", line 473, in _order_by_pairs
    yield from self.find_ordering_name(
               ~~~~~~~~~~~~~~~~~~~~~~~^
        field,
        ^^^^^^
        self.query.get_meta(),
        ^^^^^^^^^^^^^^^^^^^^^^
        default_order=default_order,
        ^^^^^^^^^^^^^^^^^^^^^^^^^^^^
    )
    ^
  File "C:\Users\kongata.AMERIDUKA.000\Desktop\finance-tracker\backend\venv\Lib\site-packages\django\db\models\sql\compiler.py", line 1113, in find_ordering_name
    for expr, is_ref in self.find_ordering_name(
                        ~~~~~~~~~~~~~~~~~~~~~~~^
        item, opts, alias, order, already_seen
        ^^^^^^^^^^^^^^^^^^^^^^^^^^^^^^^^^^^^^^
    )
    ^
  File "C:\Users\kongata.AMERIDUKA.000\Desktop\finance-tracker\backend\venv\Lib\site-packages\django\db\models\sql\compiler.py", line 1113, in find_ordering_name
    for expr, is_ref in self.find_ordering_name(
                        ~~~~~~~~~~~~~~~~~~~~~~~^
        item, opts, alias, order, already_seen
        ^^^^^^^^^^^^^^^^^^^^^^^^^^^^^^^^^^^^^^
    )
    ^
  File "C:\Users\kongata.AMERIDUKA.000\Desktop\finance-tracker\backend\venv\Lib\site-packages\django\db\models\sql\compiler.py", line 1097, in find_ordering_name
    raise FieldError("Infinite loop caused by ordering.")
django.core.exceptions.FieldError: Infinite loop caused by ordering.
ERROR 2025-08-12 02:13:53,161 basehttp 66648 71644 "GET /api/projects/ HTTP/1.1" 500 175082
ERROR 2025-08-12 02:13:53,211 log 66648 65692 Internal Server Error: /api/projects/
Traceback (most recent call last):
  File "C:\Users\kongata.AMERIDUKA.000\Desktop\finance-tracker\backend\venv\Lib\site-packages\django\core\handlers\exception.py", line 55, in inner
    response = get_response(request)
  File "C:\Users\kongata.AMERIDUKA.000\Desktop\finance-tracker\backend\venv\Lib\site-packages\django\core\handlers\base.py", line 197, in _get_response
    response = wrapped_callback(request, *callback_args, **callback_kwargs)
  File "C:\Users\kongata.AMERIDUKA.000\Desktop\finance-tracker\backend\venv\Lib\site-packages\django\views\decorators\csrf.py", line 65, in _view_wrapper
    return view_func(request, *args, **kwargs)
  File "C:\Users\kongata.AMERIDUKA.000\Desktop\finance-tracker\backend\venv\Lib\site-packages\rest_framework\viewsets.py", line 125, in view
    return self.dispatch(request, *args, **kwargs)
           ~~~~~~~~~~~~~^^^^^^^^^^^^^^^^^^^^^^^^^^
  File "C:\Users\kongata.AMERIDUKA.000\Desktop\finance-tracker\backend\venv\Lib\site-packages\rest_framework\views.py", line 515, in dispatch
    response = self.handle_exception(exc)
  File "C:\Users\kongata.AMERIDUKA.000\Desktop\finance-tracker\backend\venv\Lib\site-packages\rest_framework\views.py", line 475, in handle_exception
    self.raise_uncaught_exception(exc)
    ~~~~~~~~~~~~~~~~~~~~~~~~~~~~~^^^^^
  File "C:\Users\kongata.AMERIDUKA.000\Desktop\finance-tracker\backend\venv\Lib\site-packages\rest_framework\views.py", line 486, in raise_uncaught_exception
    raise exc
  File "C:\Users\kongata.AMERIDUKA.000\Desktop\finance-tracker\backend\venv\Lib\site-packages\rest_framework\views.py", line 512, in dispatch
    response = handler(request, *args, **kwargs)
  File "C:\Users\kongata.AMERIDUKA.000\Desktop\finance-tracker\backend\venv\Lib\site-packages\rest_framework\mixins.py", line 40, in list
    page = self.paginate_queryset(queryset)
  File "C:\Users\kongata.AMERIDUKA.000\Desktop\finance-tracker\backend\venv\Lib\site-packages\rest_framework\generics.py", line 175, in paginate_queryset
    return self.paginator.paginate_queryset(queryset, self.request, view=self)
           ~~~~~~~~~~~~~~~~~~~~~~~~~~~~~~~~^^^^^^^^^^^^^^^^^^^^^^^^^^^^^^^^^^^
  File "C:\Users\kongata.AMERIDUKA.000\Desktop\finance-tracker\backend\venv\Lib\site-packages\rest_framework\pagination.py", line 222, in paginate_queryset
    return list(self.page)
  File "C:\Users\kongata.AMERIDUKA.000\Desktop\finance-tracker\backend\venv\Lib\site-packages\django\core\paginator.py", line 191, in __len__
    return len(self.object_list)
  File "C:\Users\kongata.AMERIDUKA.000\Desktop\finance-tracker\backend\venv\Lib\site-packages\django\db\models\query.py", line 366, in __len__
    self._fetch_all()
    ~~~~~~~~~~~~~~~^^
  File "C:\Users\kongata.AMERIDUKA.000\Desktop\finance-tracker\backend\venv\Lib\site-packages\django\db\models\query.py", line 1949, in _fetch_all
    self._result_cache = list(self._iterable_class(self))
                         ~~~~^^^^^^^^^^^^^^^^^^^^^^^^^^^^
  File "C:\Users\kongata.AMERIDUKA.000\Desktop\finance-tracker\backend\venv\Lib\site-packages\django\db\models\query.py", line 91, in __iter__
    results = compiler.execute_sql(
        chunked_fetch=self.chunked_fetch, chunk_size=self.chunk_size
    )
  File "C:\Users\kongata.AMERIDUKA.000\Desktop\finance-tracker\backend\venv\Lib\site-packages\django\db\models\sql\compiler.py", line 1610, in execute_sql
    sql, params = self.as_sql()
                  ~~~~~~~~~~~^^
  File "C:\Users\kongata.AMERIDUKA.000\Desktop\finance-tracker\backend\venv\Lib\site-packages\django\db\models\sql\compiler.py", line 766, in as_sql
    extra_select, order_by, group_by = self.pre_sql_setup(
                                       ~~~~~~~~~~~~~~~~~~^
        with_col_aliases=with_col_aliases or bool(combinator),
        ^^^^^^^^^^^^^^^^^^^^^^^^^^^^^^^^^^^^^^^^^^^^^^^^^^^^^^
    )
    ^
  File "C:\Users\kongata.AMERIDUKA.000\Desktop\finance-tracker\backend\venv\Lib\site-packages\django\db\models\sql\compiler.py", line 86, in pre_sql_setup
    order_by = self.get_order_by()
  File "C:\Users\kongata.AMERIDUKA.000\Desktop\finance-tracker\backend\venv\Lib\site-packages\django\db\models\sql\compiler.py", line 490, in get_order_by
    for expr, is_ref in self._order_by_pairs():
                        ~~~~~~~~~~~~~~~~~~~~^^
  File "C:\Users\kongata.AMERIDUKA.000\Desktop\finance-tracker\backend\venv\Lib\site-packages\django\db\models\sql\compiler.py", line 473, in _order_by_pairs
    yield from self.find_ordering_name(
               ~~~~~~~~~~~~~~~~~~~~~~~^
        field,
        ^^^^^^
        self.query.get_meta(),
        ^^^^^^^^^^^^^^^^^^^^^^
        default_order=default_order,
        ^^^^^^^^^^^^^^^^^^^^^^^^^^^^
    )
    ^
  File "C:\Users\kongata.AMERIDUKA.000\Desktop\finance-tracker\backend\venv\Lib\site-packages\django\db\models\sql\compiler.py", line 1113, in find_ordering_name
    for expr, is_ref in self.find_ordering_name(
                        ~~~~~~~~~~~~~~~~~~~~~~~^
        item, opts, alias, order, already_seen
        ^^^^^^^^^^^^^^^^^^^^^^^^^^^^^^^^^^^^^^
    )
    ^
  File "C:\Users\kongata.AMERIDUKA.000\Desktop\finance-tracker\backend\venv\Lib\site-packages\django\db\models\sql\compiler.py", line 1113, in find_ordering_name
    for expr, is_ref in self.find_ordering_name(
                        ~~~~~~~~~~~~~~~~~~~~~~~^
        item, opts, alias, order, already_seen
        ^^^^^^^^^^^^^^^^^^^^^^^^^^^^^^^^^^^^^^
    )
    ^
  File "C:\Users\kongata.AMERIDUKA.000\Desktop\finance-tracker\backend\venv\Lib\site-packages\django\db\models\sql\compiler.py", line 1097, in find_ordering_name
    raise FieldError("Infinite loop caused by ordering.")
django.core.exceptions.FieldError: Infinite loop caused by ordering.
ERROR 2025-08-12 02:13:53,216 basehttp 66648 65692 "GET /api/projects/ HTTP/1.1" 500 175082
ERROR 2025-08-12 04:21:14,055 log 70024 39080 Internal Server Error: /api/dashboard/
Traceback (most recent call last):
  File "C:\Users\kongata.AMERIDUKA.000\Desktop\finance-tracker\backend\venv\Lib\site-packages\django\db\backends\utils.py", line 105, in _execute
    return self.cursor.execute(sql, params)
           ~~~~~~~~~~~~~~~~~~~^^^^^^^^^^^^^
  File "C:\Users\kongata.AMERIDUKA.000\Desktop\finance-tracker\backend\venv\Lib\site-packages\django\db\backends\sqlite3\base.py", line 360, in execute
    return super().execute(query, params)
           ~~~~~~~~~~~~~~~^^^^^^^^^^^^^^^
sqlite3.OperationalError: no such column: expense_expense.category_fk_id

The above exception was the direct cause of the following exception:

Traceback (most recent call last):
  File "C:\Users\kongata.AMERIDUKA.000\Desktop\finance-tracker\backend\venv\Lib\site-packages\django\core\handlers\exception.py", line 55, in inner
    response = get_response(request)
  File "C:\Users\kongata.AMERIDUKA.000\Desktop\finance-tracker\backend\venv\Lib\site-packages\django\core\handlers\base.py", line 197, in _get_response
    response = wrapped_callback(request, *callback_args, **callback_kwargs)
  File "C:\Users\kongata.AMERIDUKA.000\Desktop\finance-tracker\backend\venv\Lib\site-packages\django\views\decorators\csrf.py", line 65, in _view_wrapper
    return view_func(request, *args, **kwargs)
  File "C:\Users\kongata.AMERIDUKA.000\Desktop\finance-tracker\backend\venv\Lib\site-packages\django\views\generic\base.py", line 105, in view
    return self.dispatch(request, *args, **kwargs)
           ~~~~~~~~~~~~~^^^^^^^^^^^^^^^^^^^^^^^^^^
  File "C:\Users\kongata.AMERIDUKA.000\Desktop\finance-tracker\backend\venv\Lib\site-packages\rest_framework\views.py", line 515, in dispatch
    response = self.handle_exception(exc)
  File "C:\Users\kongata.AMERIDUKA.000\Desktop\finance-tracker\backend\venv\Lib\site-packages\rest_framework\views.py", line 475, in handle_exception
    self.raise_uncaught_exception(exc)
    ~~~~~~~~~~~~~~~~~~~~~~~~~~~~~^^^^^
  File "C:\Users\kongata.AMERIDUKA.000\Desktop\finance-tracker\backend\venv\Lib\site-packages\rest_framework\views.py", line 486, in raise_uncaught_exception
    raise exc
  File "C:\Users\kongata.AMERIDUKA.000\Desktop\finance-tracker\backend\venv\Lib\site-packages\rest_framework\views.py", line 512, in dispatch
    response = handler(request, *args, **kwargs)
  File "C:\Users\kongata.AMERIDUKA.000\Desktop\finance-tracker\backend\dashboard\views.py", line 81, in get
    } for e in recent_expenses
               ^^^^^^^^^^^^^^^
  File "C:\Users\kongata.AMERIDUKA.000\Desktop\finance-tracker\backend\venv\Lib\site-packages\django\db\models\query.py", line 384, in __iter__
    self._fetch_all()
    ~~~~~~~~~~~~~~~^^
  File "C:\Users\kongata.AMERIDUKA.000\Desktop\finance-tracker\backend\venv\Lib\site-packages\django\db\models\query.py", line 1949, in _fetch_all
    self._result_cache = list(self._iterable_class(self))
                         ~~~~^^^^^^^^^^^^^^^^^^^^^^^^^^^^
  File "C:\Users\kongata.AMERIDUKA.000\Desktop\finance-tracker\backend\venv\Lib\site-packages\django\db\models\query.py", line 91, in __iter__
    results = compiler.execute_sql(
        chunked_fetch=self.chunked_fetch, chunk_size=self.chunk_size
    )
  File "C:\Users\kongata.AMERIDUKA.000\Desktop\finance-tracker\backend\venv\Lib\site-packages\django\db\models\sql\compiler.py", line 1623, in execute_sql
    cursor.execute(sql, params)
    ~~~~~~~~~~~~~~^^^^^^^^^^^^^
  File "C:\Users\kongata.AMERIDUKA.000\Desktop\finance-tracker\backend\venv\Lib\site-packages\django\db\backends\utils.py", line 122, in execute
    return super().execute(sql, params)
           ~~~~~~~~~~~~~~~^^^^^^^^^^^^^
  File "C:\Users\kongata.AMERIDUKA.000\Desktop\finance-tracker\backend\venv\Lib\site-packages\django\db\backends\utils.py", line 79, in execute
    return self._execute_with_wrappers(
           ~~~~~~~~~~~~~~~~~~~~~~~~~~~^
        sql, params, many=False, executor=self._execute
        ^^^^^^^^^^^^^^^^^^^^^^^^^^^^^^^^^^^^^^^^^^^^^^^
    )
    ^
  File "C:\Users\kongata.AMERIDUKA.000\Desktop\finance-tracker\backend\venv\Lib\site-packages\django\db\backends\utils.py", line 92, in _execute_with_wrappers
    return executor(sql, params, many, context)
  File "C:\Users\kongata.AMERIDUKA.000\Desktop\finance-tracker\backend\venv\Lib\site-packages\django\db\backends\utils.py", line 100, in _execute
    with self.db.wrap_database_errors:
         ^^^^^^^^^^^^^^^^^^^^^^^^^^^^
  File "C:\Users\kongata.AMERIDUKA.000\Desktop\finance-tracker\backend\venv\Lib\site-packages\django\db\utils.py", line 91, in __exit__
    raise dj_exc_value.with_traceback(traceback) from exc_value
  File "C:\Users\kongata.AMERIDUKA.000\Desktop\finance-tracker\backend\venv\Lib\site-packages\django\db\backends\utils.py", line 105, in _execute
    return self.cursor.execute(sql, params)
           ~~~~~~~~~~~~~~~~~~~^^^^^^^^^^^^^
  File "C:\Users\kongata.AMERIDUKA.000\Desktop\finance-tracker\backend\venv\Lib\site-packages\django\db\backends\sqlite3\base.py", line 360, in execute
    return super().execute(query, params)
           ~~~~~~~~~~~~~~~^^^^^^^^^^^^^^^
django.db.utils.OperationalError: no such column: expense_expense.category_fk_id
ERROR 2025-08-12 04:21:14,064 basehttp 70024 39080 "GET /api/dashboard/ HTTP/1.1" 500 169001
ERROR 2025-08-12 04:21:14,114 log 70024 65152 Internal Server Error: /api/dashboard/
Traceback (most recent call last):
  File "C:\Users\kongata.AMERIDUKA.000\Desktop\finance-tracker\backend\venv\Lib\site-packages\django\db\backends\utils.py", line 105, in _execute
    return self.cursor.execute(sql, params)
           ~~~~~~~~~~~~~~~~~~~^^^^^^^^^^^^^
  File "C:\Users\kongata.AMERIDUKA.000\Desktop\finance-tracker\backend\venv\Lib\site-packages\django\db\backends\sqlite3\base.py", line 360, in execute
    return super().execute(query, params)
           ~~~~~~~~~~~~~~~^^^^^^^^^^^^^^^
sqlite3.OperationalError: no such column: expense_expense.category_fk_id

The above exception was the direct cause of the following exception:

Traceback (most recent call last):
  File "C:\Users\kongata.AMERIDUKA.000\Desktop\finance-tracker\backend\venv\Lib\site-packages\django\core\handlers\exception.py", line 55, in inner
    response = get_response(request)
  File "C:\Users\kongata.AMERIDUKA.000\Desktop\finance-tracker\backend\venv\Lib\site-packages\django\core\handlers\base.py", line 197, in _get_response
    response = wrapped_callback(request, *callback_args, **callback_kwargs)
  File "C:\Users\kongata.AMERIDUKA.000\Desktop\finance-tracker\backend\venv\Lib\site-packages\django\views\decorators\csrf.py", line 65, in _view_wrapper
    return view_func(request, *args, **kwargs)
  File "C:\Users\kongata.AMERIDUKA.000\Desktop\finance-tracker\backend\venv\Lib\site-packages\django\views\generic\base.py", line 105, in view
    return self.dispatch(request, *args, **kwargs)
           ~~~~~~~~~~~~~^^^^^^^^^^^^^^^^^^^^^^^^^^
  File "C:\Users\kongata.AMERIDUKA.000\Desktop\finance-tracker\backend\venv\Lib\site-packages\rest_framework\views.py", line 515, in dispatch
    response = self.handle_exception(exc)
  File "C:\Users\kongata.AMERIDUKA.000\Desktop\finance-tracker\backend\venv\Lib\site-packages\rest_framework\views.py", line 475, in handle_exception
    self.raise_uncaught_exception(exc)
    ~~~~~~~~~~~~~~~~~~~~~~~~~~~~~^^^^^
  File "C:\Users\kongata.AMERIDUKA.000\Desktop\finance-tracker\backend\venv\Lib\site-packages\rest_framework\views.py", line 486, in raise_uncaught_exception
    raise exc
  File "C:\Users\kongata.AMERIDUKA.000\Desktop\finance-tracker\backend\venv\Lib\site-packages\rest_framework\views.py", line 512, in dispatch
    response = handler(request, *args, **kwargs)
  File "C:\Users\kongata.AMERIDUKA.000\Desktop\finance-tracker\backend\dashboard\views.py", line 81, in get
    } for e in recent_expenses
               ^^^^^^^^^^^^^^^
  File "C:\Users\kongata.AMERIDUKA.000\Desktop\finance-tracker\backend\venv\Lib\site-packages\django\db\models\query.py", line 384, in __iter__
    self._fetch_all()
    ~~~~~~~~~~~~~~~^^
  File "C:\Users\kongata.AMERIDUKA.000\Desktop\finance-tracker\backend\venv\Lib\site-packages\django\db\models\query.py", line 1949, in _fetch_all
    self._result_cache = list(self._iterable_class(self))
                         ~~~~^^^^^^^^^^^^^^^^^^^^^^^^^^^^
  File "C:\Users\kongata.AMERIDUKA.000\Desktop\finance-tracker\backend\venv\Lib\site-packages\django\db\models\query.py", line 91, in __iter__
    results = compiler.execute_sql(
        chunked_fetch=self.chunked_fetch, chunk_size=self.chunk_size
    )
  File "C:\Users\kongata.AMERIDUKA.000\Desktop\finance-tracker\backend\venv\Lib\site-packages\django\db\models\sql\compiler.py", line 1623, in execute_sql
    cursor.execute(sql, params)
    ~~~~~~~~~~~~~~^^^^^^^^^^^^^
  File "C:\Users\kongata.AMERIDUKA.000\Desktop\finance-tracker\backend\venv\Lib\site-packages\django\db\backends\utils.py", line 122, in execute
    return super().execute(sql, params)
           ~~~~~~~~~~~~~~~^^^^^^^^^^^^^
  File "C:\Users\kongata.AMERIDUKA.000\Desktop\finance-tracker\backend\venv\Lib\site-packages\django\db\backends\utils.py", line 79, in execute
    return self._execute_with_wrappers(
           ~~~~~~~~~~~~~~~~~~~~~~~~~~~^
        sql, params, many=False, executor=self._execute
        ^^^^^^^^^^^^^^^^^^^^^^^^^^^^^^^^^^^^^^^^^^^^^^^
    )
    ^
  File "C:\Users\kongata.AMERIDUKA.000\Desktop\finance-tracker\backend\venv\Lib\site-packages\django\db\backends\utils.py", line 92, in _execute_with_wrappers
    return executor(sql, params, many, context)
  File "C:\Users\kongata.AMERIDUKA.000\Desktop\finance-tracker\backend\venv\Lib\site-packages\django\db\backends\utils.py", line 100, in _execute
    with self.db.wrap_database_errors:
         ^^^^^^^^^^^^^^^^^^^^^^^^^^^^
  File "C:\Users\kongata.AMERIDUKA.000\Desktop\finance-tracker\backend\venv\Lib\site-packages\django\db\utils.py", line 91, in __exit__
    raise dj_exc_value.with_traceback(traceback) from exc_value
  File "C:\Users\kongata.AMERIDUKA.000\Desktop\finance-tracker\backend\venv\Lib\site-packages\django\db\backends\utils.py", line 105, in _execute
    return self.cursor.execute(sql, params)
           ~~~~~~~~~~~~~~~~~~~^^^^^^^^^^^^^
  File "C:\Users\kongata.AMERIDUKA.000\Desktop\finance-tracker\backend\venv\Lib\site-packages\django\db\backends\sqlite3\base.py", line 360, in execute
    return super().execute(query, params)
           ~~~~~~~~~~~~~~~^^^^^^^^^^^^^^^
django.db.utils.OperationalError: no such column: expense_expense.category_fk_id
ERROR 2025-08-12 04:21:14,118 basehttp 70024 65152 "GET /api/dashboard/ HTTP/1.1" 500 169001
ERROR 2025-08-12 04:29:52,722 log 70024 64488 Internal Server Error: /api/dashboard/
Traceback (most recent call last):
  File "C:\Users\kongata.AMERIDUKA.000\Desktop\finance-tracker\backend\venv\Lib\site-packages\django\db\backends\utils.py", line 105, in _execute
    return self.cursor.execute(sql, params)
           ~~~~~~~~~~~~~~~~~~~^^^^^^^^^^^^^
  File "C:\Users\kongata.AMERIDUKA.000\Desktop\finance-tracker\backend\venv\Lib\site-packages\django\db\backends\sqlite3\base.py", line 360, in execute
    return super().execute(query, params)
           ~~~~~~~~~~~~~~~^^^^^^^^^^^^^^^
sqlite3.OperationalError: no such column: expense_expense.category_fk_id

The above exception was the direct cause of the following exception:

Traceback (most recent call last):
  File "C:\Users\kongata.AMERIDUKA.000\Desktop\finance-tracker\backend\venv\Lib\site-packages\django\core\handlers\exception.py", line 55, in inner
    response = get_response(request)
  File "C:\Users\kongata.AMERIDUKA.000\Desktop\finance-tracker\backend\venv\Lib\site-packages\django\core\handlers\base.py", line 197, in _get_response
    response = wrapped_callback(request, *callback_args, **callback_kwargs)
  File "C:\Users\kongata.AMERIDUKA.000\Desktop\finance-tracker\backend\venv\Lib\site-packages\django\views\decorators\csrf.py", line 65, in _view_wrapper
    return view_func(request, *args, **kwargs)
  File "C:\Users\kongata.AMERIDUKA.000\Desktop\finance-tracker\backend\venv\Lib\site-packages\django\views\generic\base.py", line 105, in view
    return self.dispatch(request, *args, **kwargs)
           ~~~~~~~~~~~~~^^^^^^^^^^^^^^^^^^^^^^^^^^
  File "C:\Users\kongata.AMERIDUKA.000\Desktop\finance-tracker\backend\venv\Lib\site-packages\rest_framework\views.py", line 515, in dispatch
    response = self.handle_exception(exc)
  File "C:\Users\kongata.AMERIDUKA.000\Desktop\finance-tracker\backend\venv\Lib\site-packages\rest_framework\views.py", line 475, in handle_exception
    self.raise_uncaught_exception(exc)
    ~~~~~~~~~~~~~~~~~~~~~~~~~~~~~^^^^^
  File "C:\Users\kongata.AMERIDUKA.000\Desktop\finance-tracker\backend\venv\Lib\site-packages\rest_framework\views.py", line 486, in raise_uncaught_exception
    raise exc
  File "C:\Users\kongata.AMERIDUKA.000\Desktop\finance-tracker\backend\venv\Lib\site-packages\rest_framework\views.py", line 512, in dispatch
    response = handler(request, *args, **kwargs)
  File "C:\Users\kongata.AMERIDUKA.000\Desktop\finance-tracker\backend\dashboard\views.py", line 81, in get
    } for e in recent_expenses
               ^^^^^^^^^^^^^^^
  File "C:\Users\kongata.AMERIDUKA.000\Desktop\finance-tracker\backend\venv\Lib\site-packages\django\db\models\query.py", line 384, in __iter__
    self._fetch_all()
    ~~~~~~~~~~~~~~~^^
  File "C:\Users\kongata.AMERIDUKA.000\Desktop\finance-tracker\backend\venv\Lib\site-packages\django\db\models\query.py", line 1949, in _fetch_all
    self._result_cache = list(self._iterable_class(self))
                         ~~~~^^^^^^^^^^^^^^^^^^^^^^^^^^^^
  File "C:\Users\kongata.AMERIDUKA.000\Desktop\finance-tracker\backend\venv\Lib\site-packages\django\db\models\query.py", line 91, in __iter__
    results = compiler.execute_sql(
        chunked_fetch=self.chunked_fetch, chunk_size=self.chunk_size
    )
  File "C:\Users\kongata.AMERIDUKA.000\Desktop\finance-tracker\backend\venv\Lib\site-packages\django\db\models\sql\compiler.py", line 1623, in execute_sql
    cursor.execute(sql, params)
    ~~~~~~~~~~~~~~^^^^^^^^^^^^^
  File "C:\Users\kongata.AMERIDUKA.000\Desktop\finance-tracker\backend\venv\Lib\site-packages\django\db\backends\utils.py", line 122, in execute
    return super().execute(sql, params)
           ~~~~~~~~~~~~~~~^^^^^^^^^^^^^
  File "C:\Users\kongata.AMERIDUKA.000\Desktop\finance-tracker\backend\venv\Lib\site-packages\django\db\backends\utils.py", line 79, in execute
    return self._execute_with_wrappers(
           ~~~~~~~~~~~~~~~~~~~~~~~~~~~^
        sql, params, many=False, executor=self._execute
        ^^^^^^^^^^^^^^^^^^^^^^^^^^^^^^^^^^^^^^^^^^^^^^^
    )
    ^
  File "C:\Users\kongata.AMERIDUKA.000\Desktop\finance-tracker\backend\venv\Lib\site-packages\django\db\backends\utils.py", line 92, in _execute_with_wrappers
    return executor(sql, params, many, context)
  File "C:\Users\kongata.AMERIDUKA.000\Desktop\finance-tracker\backend\venv\Lib\site-packages\django\db\backends\utils.py", line 100, in _execute
    with self.db.wrap_database_errors:
         ^^^^^^^^^^^^^^^^^^^^^^^^^^^^
  File "C:\Users\kongata.AMERIDUKA.000\Desktop\finance-tracker\backend\venv\Lib\site-packages\django\db\utils.py", line 91, in __exit__
    raise dj_exc_value.with_traceback(traceback) from exc_value
  File "C:\Users\kongata.AMERIDUKA.000\Desktop\finance-tracker\backend\venv\Lib\site-packages\django\db\backends\utils.py", line 105, in _execute
    return self.cursor.execute(sql, params)
           ~~~~~~~~~~~~~~~~~~~^^^^^^^^^^^^^
  File "C:\Users\kongata.AMERIDUKA.000\Desktop\finance-tracker\backend\venv\Lib\site-packages\django\db\backends\sqlite3\base.py", line 360, in execute
    return super().execute(query, params)
           ~~~~~~~~~~~~~~~^^^^^^^^^^^^^^^
django.db.utils.OperationalError: no such column: expense_expense.category_fk_id
ERROR 2025-08-12 04:29:52,727 basehttp 70024 64488 "GET /api/dashboard/ HTTP/1.1" 500 169001
ERROR 2025-08-12 04:29:52,766 log 70024 71000 Internal Server Error: /api/dashboard/
Traceback (most recent call last):
  File "C:\Users\kongata.AMERIDUKA.000\Desktop\finance-tracker\backend\venv\Lib\site-packages\django\db\backends\utils.py", line 105, in _execute
    return self.cursor.execute(sql, params)
           ~~~~~~~~~~~~~~~~~~~^^^^^^^^^^^^^
  File "C:\Users\kongata.AMERIDUKA.000\Desktop\finance-tracker\backend\venv\Lib\site-packages\django\db\backends\sqlite3\base.py", line 360, in execute
    return super().execute(query, params)
           ~~~~~~~~~~~~~~~^^^^^^^^^^^^^^^
sqlite3.OperationalError: no such column: expense_expense.category_fk_id

The above exception was the direct cause of the following exception:

Traceback (most recent call last):
  File "C:\Users\kongata.AMERIDUKA.000\Desktop\finance-tracker\backend\venv\Lib\site-packages\django\core\handlers\exception.py", line 55, in inner
    response = get_response(request)
  File "C:\Users\kongata.AMERIDUKA.000\Desktop\finance-tracker\backend\venv\Lib\site-packages\django\core\handlers\base.py", line 197, in _get_response
    response = wrapped_callback(request, *callback_args, **callback_kwargs)
  File "C:\Users\kongata.AMERIDUKA.000\Desktop\finance-tracker\backend\venv\Lib\site-packages\django\views\decorators\csrf.py", line 65, in _view_wrapper
    return view_func(request, *args, **kwargs)
  File "C:\Users\kongata.AMERIDUKA.000\Desktop\finance-tracker\backend\venv\Lib\site-packages\django\views\generic\base.py", line 105, in view
    return self.dispatch(request, *args, **kwargs)
           ~~~~~~~~~~~~~^^^^^^^^^^^^^^^^^^^^^^^^^^
  File "C:\Users\kongata.AMERIDUKA.000\Desktop\finance-tracker\backend\venv\Lib\site-packages\rest_framework\views.py", line 515, in dispatch
    response = self.handle_exception(exc)
  File "C:\Users\kongata.AMERIDUKA.000\Desktop\finance-tracker\backend\venv\Lib\site-packages\rest_framework\views.py", line 475, in handle_exception
    self.raise_uncaught_exception(exc)
    ~~~~~~~~~~~~~~~~~~~~~~~~~~~~~^^^^^
  File "C:\Users\kongata.AMERIDUKA.000\Desktop\finance-tracker\backend\venv\Lib\site-packages\rest_framework\views.py", line 486, in raise_uncaught_exception
    raise exc
  File "C:\Users\kongata.AMERIDUKA.000\Desktop\finance-tracker\backend\venv\Lib\site-packages\rest_framework\views.py", line 512, in dispatch
    response = handler(request, *args, **kwargs)
  File "C:\Users\kongata.AMERIDUKA.000\Desktop\finance-tracker\backend\dashboard\views.py", line 81, in get
    } for e in recent_expenses
               ^^^^^^^^^^^^^^^
  File "C:\Users\kongata.AMERIDUKA.000\Desktop\finance-tracker\backend\venv\Lib\site-packages\django\db\models\query.py", line 384, in __iter__
    self._fetch_all()
    ~~~~~~~~~~~~~~~^^
  File "C:\Users\kongata.AMERIDUKA.000\Desktop\finance-tracker\backend\venv\Lib\site-packages\django\db\models\query.py", line 1949, in _fetch_all
    self._result_cache = list(self._iterable_class(self))
                         ~~~~^^^^^^^^^^^^^^^^^^^^^^^^^^^^
  File "C:\Users\kongata.AMERIDUKA.000\Desktop\finance-tracker\backend\venv\Lib\site-packages\django\db\models\query.py", line 91, in __iter__
    results = compiler.execute_sql(
        chunked_fetch=self.chunked_fetch, chunk_size=self.chunk_size
    )
  File "C:\Users\kongata.AMERIDUKA.000\Desktop\finance-tracker\backend\venv\Lib\site-packages\django\db\models\sql\compiler.py", line 1623, in execute_sql
    cursor.execute(sql, params)
    ~~~~~~~~~~~~~~^^^^^^^^^^^^^
  File "C:\Users\kongata.AMERIDUKA.000\Desktop\finance-tracker\backend\venv\Lib\site-packages\django\db\backends\utils.py", line 122, in execute
    return super().execute(sql, params)
           ~~~~~~~~~~~~~~~^^^^^^^^^^^^^
  File "C:\Users\kongata.AMERIDUKA.000\Desktop\finance-tracker\backend\venv\Lib\site-packages\django\db\backends\utils.py", line 79, in execute
    return self._execute_with_wrappers(
           ~~~~~~~~~~~~~~~~~~~~~~~~~~~^
        sql, params, many=False, executor=self._execute
        ^^^^^^^^^^^^^^^^^^^^^^^^^^^^^^^^^^^^^^^^^^^^^^^
    )
    ^
  File "C:\Users\kongata.AMERIDUKA.000\Desktop\finance-tracker\backend\venv\Lib\site-packages\django\db\backends\utils.py", line 92, in _execute_with_wrappers
    return executor(sql, params, many, context)
  File "C:\Users\kongata.AMERIDUKA.000\Desktop\finance-tracker\backend\venv\Lib\site-packages\django\db\backends\utils.py", line 100, in _execute
    with self.db.wrap_database_errors:
         ^^^^^^^^^^^^^^^^^^^^^^^^^^^^
  File "C:\Users\kongata.AMERIDUKA.000\Desktop\finance-tracker\backend\venv\Lib\site-packages\django\db\utils.py", line 91, in __exit__
    raise dj_exc_value.with_traceback(traceback) from exc_value
  File "C:\Users\kongata.AMERIDUKA.000\Desktop\finance-tracker\backend\venv\Lib\site-packages\django\db\backends\utils.py", line 105, in _execute
    return self.cursor.execute(sql, params)
           ~~~~~~~~~~~~~~~~~~~^^^^^^^^^^^^^
  File "C:\Users\kongata.AMERIDUKA.000\Desktop\finance-tracker\backend\venv\Lib\site-packages\django\db\backends\sqlite3\base.py", line 360, in execute
    return super().execute(query, params)
           ~~~~~~~~~~~~~~~^^^^^^^^^^^^^^^
django.db.utils.OperationalError: no such column: expense_expense.category_fk_id
ERROR 2025-08-12 04:29:52,772 basehttp 70024 71000 "GET /api/dashboard/ HTTP/1.1" 500 169001
ERROR 2025-08-12 04:30:12,269 log 70024 71000 Internal Server Error: /api/dashboard/
Traceback (most recent call last):
  File "C:\Users\kongata.AMERIDUKA.000\Desktop\finance-tracker\backend\venv\Lib\site-packages\django\db\backends\utils.py", line 105, in _execute
    return self.cursor.execute(sql, params)
           ~~~~~~~~~~~~~~~~~~~^^^^^^^^^^^^^
  File "C:\Users\kongata.AMERIDUKA.000\Desktop\finance-tracker\backend\venv\Lib\site-packages\django\db\backends\sqlite3\base.py", line 360, in execute
    return super().execute(query, params)
           ~~~~~~~~~~~~~~~^^^^^^^^^^^^^^^
sqlite3.OperationalError: no such column: expense_expense.category_fk_id

The above exception was the direct cause of the following exception:

Traceback (most recent call last):
  File "C:\Users\kongata.AMERIDUKA.000\Desktop\finance-tracker\backend\venv\Lib\site-packages\django\core\handlers\exception.py", line 55, in inner
    response = get_response(request)
  File "C:\Users\kongata.AMERIDUKA.000\Desktop\finance-tracker\backend\venv\Lib\site-packages\django\core\handlers\base.py", line 197, in _get_response
    response = wrapped_callback(request, *callback_args, **callback_kwargs)
  File "C:\Users\kongata.AMERIDUKA.000\Desktop\finance-tracker\backend\venv\Lib\site-packages\django\views\decorators\csrf.py", line 65, in _view_wrapper
    return view_func(request, *args, **kwargs)
  File "C:\Users\kongata.AMERIDUKA.000\Desktop\finance-tracker\backend\venv\Lib\site-packages\django\views\generic\base.py", line 105, in view
    return self.dispatch(request, *args, **kwargs)
           ~~~~~~~~~~~~~^^^^^^^^^^^^^^^^^^^^^^^^^^
  File "C:\Users\kongata.AMERIDUKA.000\Desktop\finance-tracker\backend\venv\Lib\site-packages\rest_framework\views.py", line 515, in dispatch
    response = self.handle_exception(exc)
  File "C:\Users\kongata.AMERIDUKA.000\Desktop\finance-tracker\backend\venv\Lib\site-packages\rest_framework\views.py", line 475, in handle_exception
    self.raise_uncaught_exception(exc)
    ~~~~~~~~~~~~~~~~~~~~~~~~~~~~~^^^^^
  File "C:\Users\kongata.AMERIDUKA.000\Desktop\finance-tracker\backend\venv\Lib\site-packages\rest_framework\views.py", line 486, in raise_uncaught_exception
    raise exc
  File "C:\Users\kongata.AMERIDUKA.000\Desktop\finance-tracker\backend\venv\Lib\site-packages\rest_framework\views.py", line 512, in dispatch
    response = handler(request, *args, **kwargs)
  File "C:\Users\kongata.AMERIDUKA.000\Desktop\finance-tracker\backend\dashboard\views.py", line 81, in get
    } for e in recent_expenses
               ^^^^^^^^^^^^^^^
  File "C:\Users\kongata.AMERIDUKA.000\Desktop\finance-tracker\backend\venv\Lib\site-packages\django\db\models\query.py", line 384, in __iter__
    self._fetch_all()
    ~~~~~~~~~~~~~~~^^
  File "C:\Users\kongata.AMERIDUKA.000\Desktop\finance-tracker\backend\venv\Lib\site-packages\django\db\models\query.py", line 1949, in _fetch_all
    self._result_cache = list(self._iterable_class(self))
                         ~~~~^^^^^^^^^^^^^^^^^^^^^^^^^^^^
  File "C:\Users\kongata.AMERIDUKA.000\Desktop\finance-tracker\backend\venv\Lib\site-packages\django\db\models\query.py", line 91, in __iter__
    results = compiler.execute_sql(
        chunked_fetch=self.chunked_fetch, chunk_size=self.chunk_size
    )
  File "C:\Users\kongata.AMERIDUKA.000\Desktop\finance-tracker\backend\venv\Lib\site-packages\django\db\models\sql\compiler.py", line 1623, in execute_sql
    cursor.execute(sql, params)
    ~~~~~~~~~~~~~~^^^^^^^^^^^^^
  File "C:\Users\kongata.AMERIDUKA.000\Desktop\finance-tracker\backend\venv\Lib\site-packages\django\db\backends\utils.py", line 122, in execute
    return super().execute(sql, params)
           ~~~~~~~~~~~~~~~^^^^^^^^^^^^^
  File "C:\Users\kongata.AMERIDUKA.000\Desktop\finance-tracker\backend\venv\Lib\site-packages\django\db\backends\utils.py", line 79, in execute
    return self._execute_with_wrappers(
           ~~~~~~~~~~~~~~~~~~~~~~~~~~~^
        sql, params, many=False, executor=self._execute
        ^^^^^^^^^^^^^^^^^^^^^^^^^^^^^^^^^^^^^^^^^^^^^^^
    )
    ^
  File "C:\Users\kongata.AMERIDUKA.000\Desktop\finance-tracker\backend\venv\Lib\site-packages\django\db\backends\utils.py", line 92, in _execute_with_wrappers
    return executor(sql, params, many, context)
  File "C:\Users\kongata.AMERIDUKA.000\Desktop\finance-tracker\backend\venv\Lib\site-packages\django\db\backends\utils.py", line 100, in _execute
    with self.db.wrap_database_errors:
         ^^^^^^^^^^^^^^^^^^^^^^^^^^^^
  File "C:\Users\kongata.AMERIDUKA.000\Desktop\finance-tracker\backend\venv\Lib\site-packages\django\db\utils.py", line 91, in __exit__
    raise dj_exc_value.with_traceback(traceback) from exc_value
  File "C:\Users\kongata.AMERIDUKA.000\Desktop\finance-tracker\backend\venv\Lib\site-packages\django\db\backends\utils.py", line 105, in _execute
    return self.cursor.execute(sql, params)
           ~~~~~~~~~~~~~~~~~~~^^^^^^^^^^^^^
  File "C:\Users\kongata.AMERIDUKA.000\Desktop\finance-tracker\backend\venv\Lib\site-packages\django\db\backends\sqlite3\base.py", line 360, in execute
    return super().execute(query, params)
           ~~~~~~~~~~~~~~~^^^^^^^^^^^^^^^
django.db.utils.OperationalError: no such column: expense_expense.category_fk_id
ERROR 2025-08-12 04:30:12,272 basehttp 70024 71000 "GET /api/dashboard/ HTTP/1.1" 500 169001
ERROR 2025-08-12 04:30:12,303 log 70024 70560 Internal Server Error: /api/dashboard/
Traceback (most recent call last):
  File "C:\Users\kongata.AMERIDUKA.000\Desktop\finance-tracker\backend\venv\Lib\site-packages\django\db\backends\utils.py", line 105, in _execute
    return self.cursor.execute(sql, params)
           ~~~~~~~~~~~~~~~~~~~^^^^^^^^^^^^^
  File "C:\Users\kongata.AMERIDUKA.000\Desktop\finance-tracker\backend\venv\Lib\site-packages\django\db\backends\sqlite3\base.py", line 360, in execute
    return super().execute(query, params)
           ~~~~~~~~~~~~~~~^^^^^^^^^^^^^^^
sqlite3.OperationalError: no such column: expense_expense.category_fk_id

The above exception was the direct cause of the following exception:

Traceback (most recent call last):
  File "C:\Users\kongata.AMERIDUKA.000\Desktop\finance-tracker\backend\venv\Lib\site-packages\django\core\handlers\exception.py", line 55, in inner
    response = get_response(request)
  File "C:\Users\kongata.AMERIDUKA.000\Desktop\finance-tracker\backend\venv\Lib\site-packages\django\core\handlers\base.py", line 197, in _get_response
    response = wrapped_callback(request, *callback_args, **callback_kwargs)
  File "C:\Users\kongata.AMERIDUKA.000\Desktop\finance-tracker\backend\venv\Lib\site-packages\django\views\decorators\csrf.py", line 65, in _view_wrapper
    return view_func(request, *args, **kwargs)
  File "C:\Users\kongata.AMERIDUKA.000\Desktop\finance-tracker\backend\venv\Lib\site-packages\django\views\generic\base.py", line 105, in view
    return self.dispatch(request, *args, **kwargs)
           ~~~~~~~~~~~~~^^^^^^^^^^^^^^^^^^^^^^^^^^
  File "C:\Users\kongata.AMERIDUKA.000\Desktop\finance-tracker\backend\venv\Lib\site-packages\rest_framework\views.py", line 515, in dispatch
    response = self.handle_exception(exc)
  File "C:\Users\kongata.AMERIDUKA.000\Desktop\finance-tracker\backend\venv\Lib\site-packages\rest_framework\views.py", line 475, in handle_exception
    self.raise_uncaught_exception(exc)
    ~~~~~~~~~~~~~~~~~~~~~~~~~~~~~^^^^^
  File "C:\Users\kongata.AMERIDUKA.000\Desktop\finance-tracker\backend\venv\Lib\site-packages\rest_framework\views.py", line 486, in raise_uncaught_exception
    raise exc
  File "C:\Users\kongata.AMERIDUKA.000\Desktop\finance-tracker\backend\venv\Lib\site-packages\rest_framework\views.py", line 512, in dispatch
    response = handler(request, *args, **kwargs)
  File "C:\Users\kongata.AMERIDUKA.000\Desktop\finance-tracker\backend\dashboard\views.py", line 81, in get
    } for e in recent_expenses
               ^^^^^^^^^^^^^^^
  File "C:\Users\kongata.AMERIDUKA.000\Desktop\finance-tracker\backend\venv\Lib\site-packages\django\db\models\query.py", line 384, in __iter__
    self._fetch_all()
    ~~~~~~~~~~~~~~~^^
  File "C:\Users\kongata.AMERIDUKA.000\Desktop\finance-tracker\backend\venv\Lib\site-packages\django\db\models\query.py", line 1949, in _fetch_all
    self._result_cache = list(self._iterable_class(self))
                         ~~~~^^^^^^^^^^^^^^^^^^^^^^^^^^^^
  File "C:\Users\kongata.AMERIDUKA.000\Desktop\finance-tracker\backend\venv\Lib\site-packages\django\db\models\query.py", line 91, in __iter__
    results = compiler.execute_sql(
        chunked_fetch=self.chunked_fetch, chunk_size=self.chunk_size
    )
  File "C:\Users\kongata.AMERIDUKA.000\Desktop\finance-tracker\backend\venv\Lib\site-packages\django\db\models\sql\compiler.py", line 1623, in execute_sql
    cursor.execute(sql, params)
    ~~~~~~~~~~~~~~^^^^^^^^^^^^^
  File "C:\Users\kongata.AMERIDUKA.000\Desktop\finance-tracker\backend\venv\Lib\site-packages\django\db\backends\utils.py", line 122, in execute
    return super().execute(sql, params)
           ~~~~~~~~~~~~~~~^^^^^^^^^^^^^
  File "C:\Users\kongata.AMERIDUKA.000\Desktop\finance-tracker\backend\venv\Lib\site-packages\django\db\backends\utils.py", line 79, in execute
    return self._execute_with_wrappers(
           ~~~~~~~~~~~~~~~~~~~~~~~~~~~^
        sql, params, many=False, executor=self._execute
        ^^^^^^^^^^^^^^^^^^^^^^^^^^^^^^^^^^^^^^^^^^^^^^^
    )
    ^
  File "C:\Users\kongata.AMERIDUKA.000\Desktop\finance-tracker\backend\venv\Lib\site-packages\django\db\backends\utils.py", line 92, in _execute_with_wrappers
    return executor(sql, params, many, context)
  File "C:\Users\kongata.AMERIDUKA.000\Desktop\finance-tracker\backend\venv\Lib\site-packages\django\db\backends\utils.py", line 100, in _execute
    with self.db.wrap_database_errors:
         ^^^^^^^^^^^^^^^^^^^^^^^^^^^^
  File "C:\Users\kongata.AMERIDUKA.000\Desktop\finance-tracker\backend\venv\Lib\site-packages\django\db\utils.py", line 91, in __exit__
    raise dj_exc_value.with_traceback(traceback) from exc_value
  File "C:\Users\kongata.AMERIDUKA.000\Desktop\finance-tracker\backend\venv\Lib\site-packages\django\db\backends\utils.py", line 105, in _execute
    return self.cursor.execute(sql, params)
           ~~~~~~~~~~~~~~~~~~~^^^^^^^^^^^^^
  File "C:\Users\kongata.AMERIDUKA.000\Desktop\finance-tracker\backend\venv\Lib\site-packages\django\db\backends\sqlite3\base.py", line 360, in execute
    return super().execute(query, params)
           ~~~~~~~~~~~~~~~^^^^^^^^^^^^^^^
django.db.utils.OperationalError: no such column: expense_expense.category_fk_id
ERROR 2025-08-12 04:30:12,305 basehttp 70024 70560 "GET /api/dashboard/ HTTP/1.1" 500 169001
ERROR 2025-08-12 04:34:50,324 log 70024 70560 Internal Server Error: /api/dashboard/
Traceback (most recent call last):
  File "C:\Users\kongata.AMERIDUKA.000\Desktop\finance-tracker\backend\venv\Lib\site-packages\django\db\backends\utils.py", line 105, in _execute
    return self.cursor.execute(sql, params)
           ~~~~~~~~~~~~~~~~~~~^^^^^^^^^^^^^
  File "C:\Users\kongata.AMERIDUKA.000\Desktop\finance-tracker\backend\venv\Lib\site-packages\django\db\backends\sqlite3\base.py", line 360, in execute
    return super().execute(query, params)
           ~~~~~~~~~~~~~~~^^^^^^^^^^^^^^^
sqlite3.OperationalError: no such column: expense_expense.category_fk_id

The above exception was the direct cause of the following exception:

Traceback (most recent call last):
  File "C:\Users\kongata.AMERIDUKA.000\Desktop\finance-tracker\backend\venv\Lib\site-packages\django\core\handlers\exception.py", line 55, in inner
    response = get_response(request)
  File "C:\Users\kongata.AMERIDUKA.000\Desktop\finance-tracker\backend\venv\Lib\site-packages\django\core\handlers\base.py", line 197, in _get_response
    response = wrapped_callback(request, *callback_args, **callback_kwargs)
  File "C:\Users\kongata.AMERIDUKA.000\Desktop\finance-tracker\backend\venv\Lib\site-packages\django\views\decorators\csrf.py", line 65, in _view_wrapper
    return view_func(request, *args, **kwargs)
  File "C:\Users\kongata.AMERIDUKA.000\Desktop\finance-tracker\backend\venv\Lib\site-packages\django\views\generic\base.py", line 105, in view
    return self.dispatch(request, *args, **kwargs)
           ~~~~~~~~~~~~~^^^^^^^^^^^^^^^^^^^^^^^^^^
  File "C:\Users\kongata.AMERIDUKA.000\Desktop\finance-tracker\backend\venv\Lib\site-packages\rest_framework\views.py", line 515, in dispatch
    response = self.handle_exception(exc)
  File "C:\Users\kongata.AMERIDUKA.000\Desktop\finance-tracker\backend\venv\Lib\site-packages\rest_framework\views.py", line 475, in handle_exception
    self.raise_uncaught_exception(exc)
    ~~~~~~~~~~~~~~~~~~~~~~~~~~~~~^^^^^
  File "C:\Users\kongata.AMERIDUKA.000\Desktop\finance-tracker\backend\venv\Lib\site-packages\rest_framework\views.py", line 486, in raise_uncaught_exception
    raise exc
  File "C:\Users\kongata.AMERIDUKA.000\Desktop\finance-tracker\backend\venv\Lib\site-packages\rest_framework\views.py", line 512, in dispatch
    response = handler(request, *args, **kwargs)
  File "C:\Users\kongata.AMERIDUKA.000\Desktop\finance-tracker\backend\dashboard\views.py", line 81, in get
    } for e in recent_expenses
               ^^^^^^^^^^^^^^^
  File "C:\Users\kongata.AMERIDUKA.000\Desktop\finance-tracker\backend\venv\Lib\site-packages\django\db\models\query.py", line 384, in __iter__
    self._fetch_all()
    ~~~~~~~~~~~~~~~^^
  File "C:\Users\kongata.AMERIDUKA.000\Desktop\finance-tracker\backend\venv\Lib\site-packages\django\db\models\query.py", line 1949, in _fetch_all
    self._result_cache = list(self._iterable_class(self))
                         ~~~~^^^^^^^^^^^^^^^^^^^^^^^^^^^^
  File "C:\Users\kongata.AMERIDUKA.000\Desktop\finance-tracker\backend\venv\Lib\site-packages\django\db\models\query.py", line 91, in __iter__
    results = compiler.execute_sql(
        chunked_fetch=self.chunked_fetch, chunk_size=self.chunk_size
    )
  File "C:\Users\kongata.AMERIDUKA.000\Desktop\finance-tracker\backend\venv\Lib\site-packages\django\db\models\sql\compiler.py", line 1623, in execute_sql
    cursor.execute(sql, params)
    ~~~~~~~~~~~~~~^^^^^^^^^^^^^
  File "C:\Users\kongata.AMERIDUKA.000\Desktop\finance-tracker\backend\venv\Lib\site-packages\django\db\backends\utils.py", line 122, in execute
    return super().execute(sql, params)
           ~~~~~~~~~~~~~~~^^^^^^^^^^^^^
  File "C:\Users\kongata.AMERIDUKA.000\Desktop\finance-tracker\backend\venv\Lib\site-packages\django\db\backends\utils.py", line 79, in execute
    return self._execute_with_wrappers(
           ~~~~~~~~~~~~~~~~~~~~~~~~~~~^
        sql, params, many=False, executor=self._execute
        ^^^^^^^^^^^^^^^^^^^^^^^^^^^^^^^^^^^^^^^^^^^^^^^
    )
    ^
  File "C:\Users\kongata.AMERIDUKA.000\Desktop\finance-tracker\backend\venv\Lib\site-packages\django\db\backends\utils.py", line 92, in _execute_with_wrappers
    return executor(sql, params, many, context)
  File "C:\Users\kongata.AMERIDUKA.000\Desktop\finance-tracker\backend\venv\Lib\site-packages\django\db\backends\utils.py", line 100, in _execute
    with self.db.wrap_database_errors:
         ^^^^^^^^^^^^^^^^^^^^^^^^^^^^
  File "C:\Users\kongata.AMERIDUKA.000\Desktop\finance-tracker\backend\venv\Lib\site-packages\django\db\utils.py", line 91, in __exit__
    raise dj_exc_value.with_traceback(traceback) from exc_value
  File "C:\Users\kongata.AMERIDUKA.000\Desktop\finance-tracker\backend\venv\Lib\site-packages\django\db\backends\utils.py", line 105, in _execute
    return self.cursor.execute(sql, params)
           ~~~~~~~~~~~~~~~~~~~^^^^^^^^^^^^^
  File "C:\Users\kongata.AMERIDUKA.000\Desktop\finance-tracker\backend\venv\Lib\site-packages\django\db\backends\sqlite3\base.py", line 360, in execute
    return super().execute(query, params)
           ~~~~~~~~~~~~~~~^^^^^^^^^^^^^^^
django.db.utils.OperationalError: no such column: expense_expense.category_fk_id
ERROR 2025-08-12 04:34:50,327 basehttp 70024 70560 "GET /api/dashboard/ HTTP/1.1" 500 169001
ERROR 2025-08-12 04:34:50,370 log 70024 64488 Internal Server Error: /api/dashboard/
Traceback (most recent call last):
  File "C:\Users\kongata.AMERIDUKA.000\Desktop\finance-tracker\backend\venv\Lib\site-packages\django\db\backends\utils.py", line 105, in _execute
    return self.cursor.execute(sql, params)
           ~~~~~~~~~~~~~~~~~~~^^^^^^^^^^^^^
  File "C:\Users\kongata.AMERIDUKA.000\Desktop\finance-tracker\backend\venv\Lib\site-packages\django\db\backends\sqlite3\base.py", line 360, in execute
    return super().execute(query, params)
           ~~~~~~~~~~~~~~~^^^^^^^^^^^^^^^
sqlite3.OperationalError: no such column: expense_expense.category_fk_id

The above exception was the direct cause of the following exception:

Traceback (most recent call last):
  File "C:\Users\kongata.AMERIDUKA.000\Desktop\finance-tracker\backend\venv\Lib\site-packages\django\core\handlers\exception.py", line 55, in inner
    response = get_response(request)
  File "C:\Users\kongata.AMERIDUKA.000\Desktop\finance-tracker\backend\venv\Lib\site-packages\django\core\handlers\base.py", line 197, in _get_response
    response = wrapped_callback(request, *callback_args, **callback_kwargs)
  File "C:\Users\kongata.AMERIDUKA.000\Desktop\finance-tracker\backend\venv\Lib\site-packages\django\views\decorators\csrf.py", line 65, in _view_wrapper
    return view_func(request, *args, **kwargs)
  File "C:\Users\kongata.AMERIDUKA.000\Desktop\finance-tracker\backend\venv\Lib\site-packages\django\views\generic\base.py", line 105, in view
    return self.dispatch(request, *args, **kwargs)
           ~~~~~~~~~~~~~^^^^^^^^^^^^^^^^^^^^^^^^^^
  File "C:\Users\kongata.AMERIDUKA.000\Desktop\finance-tracker\backend\venv\Lib\site-packages\rest_framework\views.py", line 515, in dispatch
    response = self.handle_exception(exc)
  File "C:\Users\kongata.AMERIDUKA.000\Desktop\finance-tracker\backend\venv\Lib\site-packages\rest_framework\views.py", line 475, in handle_exception
    self.raise_uncaught_exception(exc)
    ~~~~~~~~~~~~~~~~~~~~~~~~~~~~~^^^^^
  File "C:\Users\kongata.AMERIDUKA.000\Desktop\finance-tracker\backend\venv\Lib\site-packages\rest_framework\views.py", line 486, in raise_uncaught_exception
    raise exc
  File "C:\Users\kongata.AMERIDUKA.000\Desktop\finance-tracker\backend\venv\Lib\site-packages\rest_framework\views.py", line 512, in dispatch
    response = handler(request, *args, **kwargs)
  File "C:\Users\kongata.AMERIDUKA.000\Desktop\finance-tracker\backend\dashboard\views.py", line 81, in get
    } for e in recent_expenses
               ^^^^^^^^^^^^^^^
  File "C:\Users\kongata.AMERIDUKA.000\Desktop\finance-tracker\backend\venv\Lib\site-packages\django\db\models\query.py", line 384, in __iter__
    self._fetch_all()
    ~~~~~~~~~~~~~~~^^
  File "C:\Users\kongata.AMERIDUKA.000\Desktop\finance-tracker\backend\venv\Lib\site-packages\django\db\models\query.py", line 1949, in _fetch_all
    self._result_cache = list(self._iterable_class(self))
                         ~~~~^^^^^^^^^^^^^^^^^^^^^^^^^^^^
  File "C:\Users\kongata.AMERIDUKA.000\Desktop\finance-tracker\backend\venv\Lib\site-packages\django\db\models\query.py", line 91, in __iter__
    results = compiler.execute_sql(
        chunked_fetch=self.chunked_fetch, chunk_size=self.chunk_size
    )
  File "C:\Users\kongata.AMERIDUKA.000\Desktop\finance-tracker\backend\venv\Lib\site-packages\django\db\models\sql\compiler.py", line 1623, in execute_sql
    cursor.execute(sql, params)
    ~~~~~~~~~~~~~~^^^^^^^^^^^^^
  File "C:\Users\kongata.AMERIDUKA.000\Desktop\finance-tracker\backend\venv\Lib\site-packages\django\db\backends\utils.py", line 122, in execute
    return super().execute(sql, params)
           ~~~~~~~~~~~~~~~^^^^^^^^^^^^^
  File "C:\Users\kongata.AMERIDUKA.000\Desktop\finance-tracker\backend\venv\Lib\site-packages\django\db\backends\utils.py", line 79, in execute
    return self._execute_with_wrappers(
           ~~~~~~~~~~~~~~~~~~~~~~~~~~~^
        sql, params, many=False, executor=self._execute
        ^^^^^^^^^^^^^^^^^^^^^^^^^^^^^^^^^^^^^^^^^^^^^^^
    )
    ^
  File "C:\Users\kongata.AMERIDUKA.000\Desktop\finance-tracker\backend\venv\Lib\site-packages\django\db\backends\utils.py", line 92, in _execute_with_wrappers
    return executor(sql, params, many, context)
  File "C:\Users\kongata.AMERIDUKA.000\Desktop\finance-tracker\backend\venv\Lib\site-packages\django\db\backends\utils.py", line 100, in _execute
    with self.db.wrap_database_errors:
         ^^^^^^^^^^^^^^^^^^^^^^^^^^^^
  File "C:\Users\kongata.AMERIDUKA.000\Desktop\finance-tracker\backend\venv\Lib\site-packages\django\db\utils.py", line 91, in __exit__
    raise dj_exc_value.with_traceback(traceback) from exc_value
  File "C:\Users\kongata.AMERIDUKA.000\Desktop\finance-tracker\backend\venv\Lib\site-packages\django\db\backends\utils.py", line 105, in _execute
    return self.cursor.execute(sql, params)
           ~~~~~~~~~~~~~~~~~~~^^^^^^^^^^^^^
  File "C:\Users\kongata.AMERIDUKA.000\Desktop\finance-tracker\backend\venv\Lib\site-packages\django\db\backends\sqlite3\base.py", line 360, in execute
    return super().execute(query, params)
           ~~~~~~~~~~~~~~~^^^^^^^^^^^^^^^
django.db.utils.OperationalError: no such column: expense_expense.category_fk_id
ERROR 2025-08-12 04:34:50,372 basehttp 70024 64488 "GET /api/dashboard/ HTTP/1.1" 500 169001
ERROR 2025-08-12 04:44:18,682 log 70024 73564 Internal Server Error: /api/dashboard/
Traceback (most recent call last):
  File "C:\Users\kongata.AMERIDUKA.000\Desktop\finance-tracker\backend\venv\Lib\site-packages\django\db\backends\utils.py", line 105, in _execute
    return self.cursor.execute(sql, params)
           ~~~~~~~~~~~~~~~~~~~^^^^^^^^^^^^^
  File "C:\Users\kongata.AMERIDUKA.000\Desktop\finance-tracker\backend\venv\Lib\site-packages\django\db\backends\sqlite3\base.py", line 360, in execute
    return super().execute(query, params)
           ~~~~~~~~~~~~~~~^^^^^^^^^^^^^^^
sqlite3.OperationalError: no such column: expense_expense.category_fk_id

The above exception was the direct cause of the following exception:

Traceback (most recent call last):
  File "C:\Users\kongata.AMERIDUKA.000\Desktop\finance-tracker\backend\venv\Lib\site-packages\django\core\handlers\exception.py", line 55, in inner
    response = get_response(request)
  File "C:\Users\kongata.AMERIDUKA.000\Desktop\finance-tracker\backend\venv\Lib\site-packages\django\core\handlers\base.py", line 197, in _get_response
    response = wrapped_callback(request, *callback_args, **callback_kwargs)
  File "C:\Users\kongata.AMERIDUKA.000\Desktop\finance-tracker\backend\venv\Lib\site-packages\django\views\decorators\csrf.py", line 65, in _view_wrapper
    return view_func(request, *args, **kwargs)
  File "C:\Users\kongata.AMERIDUKA.000\Desktop\finance-tracker\backend\venv\Lib\site-packages\django\views\generic\base.py", line 105, in view
    return self.dispatch(request, *args, **kwargs)
           ~~~~~~~~~~~~~^^^^^^^^^^^^^^^^^^^^^^^^^^
  File "C:\Users\kongata.AMERIDUKA.000\Desktop\finance-tracker\backend\venv\Lib\site-packages\rest_framework\views.py", line 515, in dispatch
    response = self.handle_exception(exc)
  File "C:\Users\kongata.AMERIDUKA.000\Desktop\finance-tracker\backend\venv\Lib\site-packages\rest_framework\views.py", line 475, in handle_exception
    self.raise_uncaught_exception(exc)
    ~~~~~~~~~~~~~~~~~~~~~~~~~~~~~^^^^^
  File "C:\Users\kongata.AMERIDUKA.000\Desktop\finance-tracker\backend\venv\Lib\site-packages\rest_framework\views.py", line 486, in raise_uncaught_exception
    raise exc
  File "C:\Users\kongata.AMERIDUKA.000\Desktop\finance-tracker\backend\venv\Lib\site-packages\rest_framework\views.py", line 512, in dispatch
    response = handler(request, *args, **kwargs)
  File "C:\Users\kongata.AMERIDUKA.000\Desktop\finance-tracker\backend\dashboard\views.py", line 81, in get
    } for e in recent_expenses
               ^^^^^^^^^^^^^^^
  File "C:\Users\kongata.AMERIDUKA.000\Desktop\finance-tracker\backend\venv\Lib\site-packages\django\db\models\query.py", line 384, in __iter__
    self._fetch_all()
    ~~~~~~~~~~~~~~~^^
  File "C:\Users\kongata.AMERIDUKA.000\Desktop\finance-tracker\backend\venv\Lib\site-packages\django\db\models\query.py", line 1949, in _fetch_all
    self._result_cache = list(self._iterable_class(self))
                         ~~~~^^^^^^^^^^^^^^^^^^^^^^^^^^^^
  File "C:\Users\kongata.AMERIDUKA.000\Desktop\finance-tracker\backend\venv\Lib\site-packages\django\db\models\query.py", line 91, in __iter__
    results = compiler.execute_sql(
        chunked_fetch=self.chunked_fetch, chunk_size=self.chunk_size
    )
  File "C:\Users\kongata.AMERIDUKA.000\Desktop\finance-tracker\backend\venv\Lib\site-packages\django\db\models\sql\compiler.py", line 1623, in execute_sql
    cursor.execute(sql, params)
    ~~~~~~~~~~~~~~^^^^^^^^^^^^^
  File "C:\Users\kongata.AMERIDUKA.000\Desktop\finance-tracker\backend\venv\Lib\site-packages\django\db\backends\utils.py", line 122, in execute
    return super().execute(sql, params)
           ~~~~~~~~~~~~~~~^^^^^^^^^^^^^
  File "C:\Users\kongata.AMERIDUKA.000\Desktop\finance-tracker\backend\venv\Lib\site-packages\django\db\backends\utils.py", line 79, in execute
    return self._execute_with_wrappers(
           ~~~~~~~~~~~~~~~~~~~~~~~~~~~^
        sql, params, many=False, executor=self._execute
        ^^^^^^^^^^^^^^^^^^^^^^^^^^^^^^^^^^^^^^^^^^^^^^^
    )
    ^
  File "C:\Users\kongata.AMERIDUKA.000\Desktop\finance-tracker\backend\venv\Lib\site-packages\django\db\backends\utils.py", line 92, in _execute_with_wrappers
    return executor(sql, params, many, context)
  File "C:\Users\kongata.AMERIDUKA.000\Desktop\finance-tracker\backend\venv\Lib\site-packages\django\db\backends\utils.py", line 100, in _execute
    with self.db.wrap_database_errors:
         ^^^^^^^^^^^^^^^^^^^^^^^^^^^^
  File "C:\Users\kongata.AMERIDUKA.000\Desktop\finance-tracker\backend\venv\Lib\site-packages\django\db\utils.py", line 91, in __exit__
    raise dj_exc_value.with_traceback(traceback) from exc_value
  File "C:\Users\kongata.AMERIDUKA.000\Desktop\finance-tracker\backend\venv\Lib\site-packages\django\db\backends\utils.py", line 105, in _execute
    return self.cursor.execute(sql, params)
           ~~~~~~~~~~~~~~~~~~~^^^^^^^^^^^^^
  File "C:\Users\kongata.AMERIDUKA.000\Desktop\finance-tracker\backend\venv\Lib\site-packages\django\db\backends\sqlite3\base.py", line 360, in execute
    return super().execute(query, params)
           ~~~~~~~~~~~~~~~^^^^^^^^^^^^^^^
django.db.utils.OperationalError: no such column: expense_expense.category_fk_id
ERROR 2025-08-12 04:44:18,685 basehttp 70024 73564 "GET /api/dashboard/ HTTP/1.1" 500 169001
ERROR 2025-08-12 04:44:18,715 log 70024 29484 Internal Server Error: /api/dashboard/
Traceback (most recent call last):
  File "C:\Users\kongata.AMERIDUKA.000\Desktop\finance-tracker\backend\venv\Lib\site-packages\django\db\backends\utils.py", line 105, in _execute
    return self.cursor.execute(sql, params)
           ~~~~~~~~~~~~~~~~~~~^^^^^^^^^^^^^
  File "C:\Users\kongata.AMERIDUKA.000\Desktop\finance-tracker\backend\venv\Lib\site-packages\django\db\backends\sqlite3\base.py", line 360, in execute
    return super().execute(query, params)
           ~~~~~~~~~~~~~~~^^^^^^^^^^^^^^^
sqlite3.OperationalError: no such column: expense_expense.category_fk_id

The above exception was the direct cause of the following exception:

Traceback (most recent call last):
  File "C:\Users\kongata.AMERIDUKA.000\Desktop\finance-tracker\backend\venv\Lib\site-packages\django\core\handlers\exception.py", line 55, in inner
    response = get_response(request)
  File "C:\Users\kongata.AMERIDUKA.000\Desktop\finance-tracker\backend\venv\Lib\site-packages\django\core\handlers\base.py", line 197, in _get_response
    response = wrapped_callback(request, *callback_args, **callback_kwargs)
  File "C:\Users\kongata.AMERIDUKA.000\Desktop\finance-tracker\backend\venv\Lib\site-packages\django\views\decorators\csrf.py", line 65, in _view_wrapper
    return view_func(request, *args, **kwargs)
  File "C:\Users\kongata.AMERIDUKA.000\Desktop\finance-tracker\backend\venv\Lib\site-packages\django\views\generic\base.py", line 105, in view
    return self.dispatch(request, *args, **kwargs)
           ~~~~~~~~~~~~~^^^^^^^^^^^^^^^^^^^^^^^^^^
  File "C:\Users\kongata.AMERIDUKA.000\Desktop\finance-tracker\backend\venv\Lib\site-packages\rest_framework\views.py", line 515, in dispatch
    response = self.handle_exception(exc)
  File "C:\Users\kongata.AMERIDUKA.000\Desktop\finance-tracker\backend\venv\Lib\site-packages\rest_framework\views.py", line 475, in handle_exception
    self.raise_uncaught_exception(exc)
    ~~~~~~~~~~~~~~~~~~~~~~~~~~~~~^^^^^
  File "C:\Users\kongata.AMERIDUKA.000\Desktop\finance-tracker\backend\venv\Lib\site-packages\rest_framework\views.py", line 486, in raise_uncaught_exception
    raise exc
  File "C:\Users\kongata.AMERIDUKA.000\Desktop\finance-tracker\backend\venv\Lib\site-packages\rest_framework\views.py", line 512, in dispatch
    response = handler(request, *args, **kwargs)
  File "C:\Users\kongata.AMERIDUKA.000\Desktop\finance-tracker\backend\dashboard\views.py", line 81, in get
    } for e in recent_expenses
               ^^^^^^^^^^^^^^^
  File "C:\Users\kongata.AMERIDUKA.000\Desktop\finance-tracker\backend\venv\Lib\site-packages\django\db\models\query.py", line 384, in __iter__
    self._fetch_all()
    ~~~~~~~~~~~~~~~^^
  File "C:\Users\kongata.AMERIDUKA.000\Desktop\finance-tracker\backend\venv\Lib\site-packages\django\db\models\query.py", line 1949, in _fetch_all
    self._result_cache = list(self._iterable_class(self))
                         ~~~~^^^^^^^^^^^^^^^^^^^^^^^^^^^^
  File "C:\Users\kongata.AMERIDUKA.000\Desktop\finance-tracker\backend\venv\Lib\site-packages\django\db\models\query.py", line 91, in __iter__
    results = compiler.execute_sql(
        chunked_fetch=self.chunked_fetch, chunk_size=self.chunk_size
    )
  File "C:\Users\kongata.AMERIDUKA.000\Desktop\finance-tracker\backend\venv\Lib\site-packages\django\db\models\sql\compiler.py", line 1623, in execute_sql
    cursor.execute(sql, params)
    ~~~~~~~~~~~~~~^^^^^^^^^^^^^
  File "C:\Users\kongata.AMERIDUKA.000\Desktop\finance-tracker\backend\venv\Lib\site-packages\django\db\backends\utils.py", line 122, in execute
    return super().execute(sql, params)
           ~~~~~~~~~~~~~~~^^^^^^^^^^^^^
  File "C:\Users\kongata.AMERIDUKA.000\Desktop\finance-tracker\backend\venv\Lib\site-packages\django\db\backends\utils.py", line 79, in execute
    return self._execute_with_wrappers(
           ~~~~~~~~~~~~~~~~~~~~~~~~~~~^
        sql, params, many=False, executor=self._execute
        ^^^^^^^^^^^^^^^^^^^^^^^^^^^^^^^^^^^^^^^^^^^^^^^
    )
    ^
  File "C:\Users\kongata.AMERIDUKA.000\Desktop\finance-tracker\backend\venv\Lib\site-packages\django\db\backends\utils.py", line 92, in _execute_with_wrappers
    return executor(sql, params, many, context)
  File "C:\Users\kongata.AMERIDUKA.000\Desktop\finance-tracker\backend\venv\Lib\site-packages\django\db\backends\utils.py", line 100, in _execute
    with self.db.wrap_database_errors:
         ^^^^^^^^^^^^^^^^^^^^^^^^^^^^
  File "C:\Users\kongata.AMERIDUKA.000\Desktop\finance-tracker\backend\venv\Lib\site-packages\django\db\utils.py", line 91, in __exit__
    raise dj_exc_value.with_traceback(traceback) from exc_value
  File "C:\Users\kongata.AMERIDUKA.000\Desktop\finance-tracker\backend\venv\Lib\site-packages\django\db\backends\utils.py", line 105, in _execute
    return self.cursor.execute(sql, params)
           ~~~~~~~~~~~~~~~~~~~^^^^^^^^^^^^^
  File "C:\Users\kongata.AMERIDUKA.000\Desktop\finance-tracker\backend\venv\Lib\site-packages\django\db\backends\sqlite3\base.py", line 360, in execute
    return super().execute(query, params)
           ~~~~~~~~~~~~~~~^^^^^^^^^^^^^^^
django.db.utils.OperationalError: no such column: expense_expense.category_fk_id
ERROR 2025-08-12 04:44:18,717 basehttp 70024 29484 "GET /api/dashboard/ HTTP/1.1" 500 169001
ERROR 2025-08-12 04:44:39,780 log 70024 29484 Internal Server Error: /api/dashboard/
Traceback (most recent call last):
  File "C:\Users\kongata.AMERIDUKA.000\Desktop\finance-tracker\backend\venv\Lib\site-packages\django\db\backends\utils.py", line 105, in _execute
    return self.cursor.execute(sql, params)
           ~~~~~~~~~~~~~~~~~~~^^^^^^^^^^^^^
  File "C:\Users\kongata.AMERIDUKA.000\Desktop\finance-tracker\backend\venv\Lib\site-packages\django\db\backends\sqlite3\base.py", line 360, in execute
    return super().execute(query, params)
           ~~~~~~~~~~~~~~~^^^^^^^^^^^^^^^
sqlite3.OperationalError: no such column: expense_expense.category_fk_id

The above exception was the direct cause of the following exception:

Traceback (most recent call last):
  File "C:\Users\kongata.AMERIDUKA.000\Desktop\finance-tracker\backend\venv\Lib\site-packages\django\core\handlers\exception.py", line 55, in inner
    response = get_response(request)
  File "C:\Users\kongata.AMERIDUKA.000\Desktop\finance-tracker\backend\venv\Lib\site-packages\django\core\handlers\base.py", line 197, in _get_response
    response = wrapped_callback(request, *callback_args, **callback_kwargs)
  File "C:\Users\kongata.AMERIDUKA.000\Desktop\finance-tracker\backend\venv\Lib\site-packages\django\views\decorators\csrf.py", line 65, in _view_wrapper
    return view_func(request, *args, **kwargs)
  File "C:\Users\kongata.AMERIDUKA.000\Desktop\finance-tracker\backend\venv\Lib\site-packages\django\views\generic\base.py", line 105, in view
    return self.dispatch(request, *args, **kwargs)
           ~~~~~~~~~~~~~^^^^^^^^^^^^^^^^^^^^^^^^^^
  File "C:\Users\kongata.AMERIDUKA.000\Desktop\finance-tracker\backend\venv\Lib\site-packages\rest_framework\views.py", line 515, in dispatch
    response = self.handle_exception(exc)
  File "C:\Users\kongata.AMERIDUKA.000\Desktop\finance-tracker\backend\venv\Lib\site-packages\rest_framework\views.py", line 475, in handle_exception
    self.raise_uncaught_exception(exc)
    ~~~~~~~~~~~~~~~~~~~~~~~~~~~~~^^^^^
  File "C:\Users\kongata.AMERIDUKA.000\Desktop\finance-tracker\backend\venv\Lib\site-packages\rest_framework\views.py", line 486, in raise_uncaught_exception
    raise exc
  File "C:\Users\kongata.AMERIDUKA.000\Desktop\finance-tracker\backend\venv\Lib\site-packages\rest_framework\views.py", line 512, in dispatch
    response = handler(request, *args, **kwargs)
  File "C:\Users\kongata.AMERIDUKA.000\Desktop\finance-tracker\backend\dashboard\views.py", line 81, in get
    } for e in recent_expenses
               ^^^^^^^^^^^^^^^
  File "C:\Users\kongata.AMERIDUKA.000\Desktop\finance-tracker\backend\venv\Lib\site-packages\django\db\models\query.py", line 384, in __iter__
    self._fetch_all()
    ~~~~~~~~~~~~~~~^^
  File "C:\Users\kongata.AMERIDUKA.000\Desktop\finance-tracker\backend\venv\Lib\site-packages\django\db\models\query.py", line 1949, in _fetch_all
    self._result_cache = list(self._iterable_class(self))
                         ~~~~^^^^^^^^^^^^^^^^^^^^^^^^^^^^
  File "C:\Users\kongata.AMERIDUKA.000\Desktop\finance-tracker\backend\venv\Lib\site-packages\django\db\models\query.py", line 91, in __iter__
    results = compiler.execute_sql(
        chunked_fetch=self.chunked_fetch, chunk_size=self.chunk_size
    )
  File "C:\Users\kongata.AMERIDUKA.000\Desktop\finance-tracker\backend\venv\Lib\site-packages\django\db\models\sql\compiler.py", line 1623, in execute_sql
    cursor.execute(sql, params)
    ~~~~~~~~~~~~~~^^^^^^^^^^^^^
  File "C:\Users\kongata.AMERIDUKA.000\Desktop\finance-tracker\backend\venv\Lib\site-packages\django\db\backends\utils.py", line 122, in execute
    return super().execute(sql, params)
           ~~~~~~~~~~~~~~~^^^^^^^^^^^^^
  File "C:\Users\kongata.AMERIDUKA.000\Desktop\finance-tracker\backend\venv\Lib\site-packages\django\db\backends\utils.py", line 79, in execute
    return self._execute_with_wrappers(
           ~~~~~~~~~~~~~~~~~~~~~~~~~~~^
        sql, params, many=False, executor=self._execute
        ^^^^^^^^^^^^^^^^^^^^^^^^^^^^^^^^^^^^^^^^^^^^^^^
    )
    ^
  File "C:\Users\kongata.AMERIDUKA.000\Desktop\finance-tracker\backend\venv\Lib\site-packages\django\db\backends\utils.py", line 92, in _execute_with_wrappers
    return executor(sql, params, many, context)
  File "C:\Users\kongata.AMERIDUKA.000\Desktop\finance-tracker\backend\venv\Lib\site-packages\django\db\backends\utils.py", line 100, in _execute
    with self.db.wrap_database_errors:
         ^^^^^^^^^^^^^^^^^^^^^^^^^^^^
  File "C:\Users\kongata.AMERIDUKA.000\Desktop\finance-tracker\backend\venv\Lib\site-packages\django\db\utils.py", line 91, in __exit__
    raise dj_exc_value.with_traceback(traceback) from exc_value
  File "C:\Users\kongata.AMERIDUKA.000\Desktop\finance-tracker\backend\venv\Lib\site-packages\django\db\backends\utils.py", line 105, in _execute
    return self.cursor.execute(sql, params)
           ~~~~~~~~~~~~~~~~~~~^^^^^^^^^^^^^
  File "C:\Users\kongata.AMERIDUKA.000\Desktop\finance-tracker\backend\venv\Lib\site-packages\django\db\backends\sqlite3\base.py", line 360, in execute
    return super().execute(query, params)
           ~~~~~~~~~~~~~~~^^^^^^^^^^^^^^^
django.db.utils.OperationalError: no such column: expense_expense.category_fk_id
ERROR 2025-08-12 04:44:39,782 basehttp 70024 29484 "GET /api/dashboard/ HTTP/1.1" 500 169001
ERROR 2025-08-12 04:44:39,813 log 70024 72576 Internal Server Error: /api/dashboard/
Traceback (most recent call last):
  File "C:\Users\kongata.AMERIDUKA.000\Desktop\finance-tracker\backend\venv\Lib\site-packages\django\db\backends\utils.py", line 105, in _execute
    return self.cursor.execute(sql, params)
           ~~~~~~~~~~~~~~~~~~~^^^^^^^^^^^^^
  File "C:\Users\kongata.AMERIDUKA.000\Desktop\finance-tracker\backend\venv\Lib\site-packages\django\db\backends\sqlite3\base.py", line 360, in execute
    return super().execute(query, params)
           ~~~~~~~~~~~~~~~^^^^^^^^^^^^^^^
sqlite3.OperationalError: no such column: expense_expense.category_fk_id

The above exception was the direct cause of the following exception:

Traceback (most recent call last):
  File "C:\Users\kongata.AMERIDUKA.000\Desktop\finance-tracker\backend\venv\Lib\site-packages\django\core\handlers\exception.py", line 55, in inner
    response = get_response(request)
  File "C:\Users\kongata.AMERIDUKA.000\Desktop\finance-tracker\backend\venv\Lib\site-packages\django\core\handlers\base.py", line 197, in _get_response
    response = wrapped_callback(request, *callback_args, **callback_kwargs)
  File "C:\Users\kongata.AMERIDUKA.000\Desktop\finance-tracker\backend\venv\Lib\site-packages\django\views\decorators\csrf.py", line 65, in _view_wrapper
    return view_func(request, *args, **kwargs)
  File "C:\Users\kongata.AMERIDUKA.000\Desktop\finance-tracker\backend\venv\Lib\site-packages\django\views\generic\base.py", line 105, in view
    return self.dispatch(request, *args, **kwargs)
           ~~~~~~~~~~~~~^^^^^^^^^^^^^^^^^^^^^^^^^^
  File "C:\Users\kongata.AMERIDUKA.000\Desktop\finance-tracker\backend\venv\Lib\site-packages\rest_framework\views.py", line 515, in dispatch
    response = self.handle_exception(exc)
  File "C:\Users\kongata.AMERIDUKA.000\Desktop\finance-tracker\backend\venv\Lib\site-packages\rest_framework\views.py", line 475, in handle_exception
    self.raise_uncaught_exception(exc)
    ~~~~~~~~~~~~~~~~~~~~~~~~~~~~~^^^^^
  File "C:\Users\kongata.AMERIDUKA.000\Desktop\finance-tracker\backend\venv\Lib\site-packages\rest_framework\views.py", line 486, in raise_uncaught_exception
    raise exc
  File "C:\Users\kongata.AMERIDUKA.000\Desktop\finance-tracker\backend\venv\Lib\site-packages\rest_framework\views.py", line 512, in dispatch
    response = handler(request, *args, **kwargs)
  File "C:\Users\kongata.AMERIDUKA.000\Desktop\finance-tracker\backend\dashboard\views.py", line 81, in get
    } for e in recent_expenses
               ^^^^^^^^^^^^^^^
  File "C:\Users\kongata.AMERIDUKA.000\Desktop\finance-tracker\backend\venv\Lib\site-packages\django\db\models\query.py", line 384, in __iter__
    self._fetch_all()
    ~~~~~~~~~~~~~~~^^
  File "C:\Users\kongata.AMERIDUKA.000\Desktop\finance-tracker\backend\venv\Lib\site-packages\django\db\models\query.py", line 1949, in _fetch_all
    self._result_cache = list(self._iterable_class(self))
                         ~~~~^^^^^^^^^^^^^^^^^^^^^^^^^^^^
  File "C:\Users\kongata.AMERIDUKA.000\Desktop\finance-tracker\backend\venv\Lib\site-packages\django\db\models\query.py", line 91, in __iter__
    results = compiler.execute_sql(
        chunked_fetch=self.chunked_fetch, chunk_size=self.chunk_size
    )
  File "C:\Users\kongata.AMERIDUKA.000\Desktop\finance-tracker\backend\venv\Lib\site-packages\django\db\models\sql\compiler.py", line 1623, in execute_sql
    cursor.execute(sql, params)
    ~~~~~~~~~~~~~~^^^^^^^^^^^^^
  File "C:\Users\kongata.AMERIDUKA.000\Desktop\finance-tracker\backend\venv\Lib\site-packages\django\db\backends\utils.py", line 122, in execute
    return super().execute(sql, params)
           ~~~~~~~~~~~~~~~^^^^^^^^^^^^^
  File "C:\Users\kongata.AMERIDUKA.000\Desktop\finance-tracker\backend\venv\Lib\site-packages\django\db\backends\utils.py", line 79, in execute
    return self._execute_with_wrappers(
           ~~~~~~~~~~~~~~~~~~~~~~~~~~~^
        sql, params, many=False, executor=self._execute
        ^^^^^^^^^^^^^^^^^^^^^^^^^^^^^^^^^^^^^^^^^^^^^^^
    )
    ^
  File "C:\Users\kongata.AMERIDUKA.000\Desktop\finance-tracker\backend\venv\Lib\site-packages\django\db\backends\utils.py", line 92, in _execute_with_wrappers
    return executor(sql, params, many, context)
  File "C:\Users\kongata.AMERIDUKA.000\Desktop\finance-tracker\backend\venv\Lib\site-packages\django\db\backends\utils.py", line 100, in _execute
    with self.db.wrap_database_errors:
         ^^^^^^^^^^^^^^^^^^^^^^^^^^^^
  File "C:\Users\kongata.AMERIDUKA.000\Desktop\finance-tracker\backend\venv\Lib\site-packages\django\db\utils.py", line 91, in __exit__
    raise dj_exc_value.with_traceback(traceback) from exc_value
  File "C:\Users\kongata.AMERIDUKA.000\Desktop\finance-tracker\backend\venv\Lib\site-packages\django\db\backends\utils.py", line 105, in _execute
    return self.cursor.execute(sql, params)
           ~~~~~~~~~~~~~~~~~~~^^^^^^^^^^^^^
  File "C:\Users\kongata.AMERIDUKA.000\Desktop\finance-tracker\backend\venv\Lib\site-packages\django\db\backends\sqlite3\base.py", line 360, in execute
    return super().execute(query, params)
           ~~~~~~~~~~~~~~~^^^^^^^^^^^^^^^
django.db.utils.OperationalError: no such column: expense_expense.category_fk_id
ERROR 2025-08-12 04:44:39,815 basehttp 70024 72576 "GET /api/dashboard/ HTTP/1.1" 500 169001
ERROR 2025-08-12 04:45:08,006 log 70024 70432 Internal Server Error: /api/dashboard/
Traceback (most recent call last):
  File "C:\Users\kongata.AMERIDUKA.000\Desktop\finance-tracker\backend\venv\Lib\site-packages\django\db\backends\utils.py", line 105, in _execute
    return self.cursor.execute(sql, params)
           ~~~~~~~~~~~~~~~~~~~^^^^^^^^^^^^^
  File "C:\Users\kongata.AMERIDUKA.000\Desktop\finance-tracker\backend\venv\Lib\site-packages\django\db\backends\sqlite3\base.py", line 360, in execute
    return super().execute(query, params)
           ~~~~~~~~~~~~~~~^^^^^^^^^^^^^^^
sqlite3.OperationalError: no such column: expense_expense.category_fk_id

The above exception was the direct cause of the following exception:

Traceback (most recent call last):
  File "C:\Users\kongata.AMERIDUKA.000\Desktop\finance-tracker\backend\venv\Lib\site-packages\django\core\handlers\exception.py", line 55, in inner
    response = get_response(request)
  File "C:\Users\kongata.AMERIDUKA.000\Desktop\finance-tracker\backend\venv\Lib\site-packages\django\core\handlers\base.py", line 197, in _get_response
    response = wrapped_callback(request, *callback_args, **callback_kwargs)
  File "C:\Users\kongata.AMERIDUKA.000\Desktop\finance-tracker\backend\venv\Lib\site-packages\django\views\decorators\csrf.py", line 65, in _view_wrapper
    return view_func(request, *args, **kwargs)
  File "C:\Users\kongata.AMERIDUKA.000\Desktop\finance-tracker\backend\venv\Lib\site-packages\django\views\generic\base.py", line 105, in view
    return self.dispatch(request, *args, **kwargs)
           ~~~~~~~~~~~~~^^^^^^^^^^^^^^^^^^^^^^^^^^
  File "C:\Users\kongata.AMERIDUKA.000\Desktop\finance-tracker\backend\venv\Lib\site-packages\rest_framework\views.py", line 515, in dispatch
    response = self.handle_exception(exc)
  File "C:\Users\kongata.AMERIDUKA.000\Desktop\finance-tracker\backend\venv\Lib\site-packages\rest_framework\views.py", line 475, in handle_exception
    self.raise_uncaught_exception(exc)
    ~~~~~~~~~~~~~~~~~~~~~~~~~~~~~^^^^^
  File "C:\Users\kongata.AMERIDUKA.000\Desktop\finance-tracker\backend\venv\Lib\site-packages\rest_framework\views.py", line 486, in raise_uncaught_exception
    raise exc
  File "C:\Users\kongata.AMERIDUKA.000\Desktop\finance-tracker\backend\venv\Lib\site-packages\rest_framework\views.py", line 512, in dispatch
    response = handler(request, *args, **kwargs)
  File "C:\Users\kongata.AMERIDUKA.000\Desktop\finance-tracker\backend\dashboard\views.py", line 81, in get
    } for e in recent_expenses
               ^^^^^^^^^^^^^^^
  File "C:\Users\kongata.AMERIDUKA.000\Desktop\finance-tracker\backend\venv\Lib\site-packages\django\db\models\query.py", line 384, in __iter__
    self._fetch_all()
    ~~~~~~~~~~~~~~~^^
  File "C:\Users\kongata.AMERIDUKA.000\Desktop\finance-tracker\backend\venv\Lib\site-packages\django\db\models\query.py", line 1949, in _fetch_all
    self._result_cache = list(self._iterable_class(self))
                         ~~~~^^^^^^^^^^^^^^^^^^^^^^^^^^^^
  File "C:\Users\kongata.AMERIDUKA.000\Desktop\finance-tracker\backend\venv\Lib\site-packages\django\db\models\query.py", line 91, in __iter__
    results = compiler.execute_sql(
        chunked_fetch=self.chunked_fetch, chunk_size=self.chunk_size
    )
  File "C:\Users\kongata.AMERIDUKA.000\Desktop\finance-tracker\backend\venv\Lib\site-packages\django\db\models\sql\compiler.py", line 1623, in execute_sql
    cursor.execute(sql, params)
    ~~~~~~~~~~~~~~^^^^^^^^^^^^^
  File "C:\Users\kongata.AMERIDUKA.000\Desktop\finance-tracker\backend\venv\Lib\site-packages\django\db\backends\utils.py", line 122, in execute
    return super().execute(sql, params)
           ~~~~~~~~~~~~~~~^^^^^^^^^^^^^
  File "C:\Users\kongata.AMERIDUKA.000\Desktop\finance-tracker\backend\venv\Lib\site-packages\django\db\backends\utils.py", line 79, in execute
    return self._execute_with_wrappers(
           ~~~~~~~~~~~~~~~~~~~~~~~~~~~^
        sql, params, many=False, executor=self._execute
        ^^^^^^^^^^^^^^^^^^^^^^^^^^^^^^^^^^^^^^^^^^^^^^^
    )
    ^
  File "C:\Users\kongata.AMERIDUKA.000\Desktop\finance-tracker\backend\venv\Lib\site-packages\django\db\backends\utils.py", line 92, in _execute_with_wrappers
    return executor(sql, params, many, context)
  File "C:\Users\kongata.AMERIDUKA.000\Desktop\finance-tracker\backend\venv\Lib\site-packages\django\db\backends\utils.py", line 100, in _execute
    with self.db.wrap_database_errors:
         ^^^^^^^^^^^^^^^^^^^^^^^^^^^^
  File "C:\Users\kongata.AMERIDUKA.000\Desktop\finance-tracker\backend\venv\Lib\site-packages\django\db\utils.py", line 91, in __exit__
    raise dj_exc_value.with_traceback(traceback) from exc_value
  File "C:\Users\kongata.AMERIDUKA.000\Desktop\finance-tracker\backend\venv\Lib\site-packages\django\db\backends\utils.py", line 105, in _execute
    return self.cursor.execute(sql, params)
           ~~~~~~~~~~~~~~~~~~~^^^^^^^^^^^^^
  File "C:\Users\kongata.AMERIDUKA.000\Desktop\finance-tracker\backend\venv\Lib\site-packages\django\db\backends\sqlite3\base.py", line 360, in execute
    return super().execute(query, params)
           ~~~~~~~~~~~~~~~^^^^^^^^^^^^^^^
django.db.utils.OperationalError: no such column: expense_expense.category_fk_id
ERROR 2025-08-12 04:45:08,008 basehttp 70024 70432 "GET /api/dashboard/ HTTP/1.1" 500 169001
ERROR 2025-08-12 04:45:08,040 log 70024 29484 Internal Server Error: /api/dashboard/
Traceback (most recent call last):
  File "C:\Users\kongata.AMERIDUKA.000\Desktop\finance-tracker\backend\venv\Lib\site-packages\django\db\backends\utils.py", line 105, in _execute
    return self.cursor.execute(sql, params)
           ~~~~~~~~~~~~~~~~~~~^^^^^^^^^^^^^
  File "C:\Users\kongata.AMERIDUKA.000\Desktop\finance-tracker\backend\venv\Lib\site-packages\django\db\backends\sqlite3\base.py", line 360, in execute
    return super().execute(query, params)
           ~~~~~~~~~~~~~~~^^^^^^^^^^^^^^^
sqlite3.OperationalError: no such column: expense_expense.category_fk_id

The above exception was the direct cause of the following exception:

Traceback (most recent call last):
  File "C:\Users\kongata.AMERIDUKA.000\Desktop\finance-tracker\backend\venv\Lib\site-packages\django\core\handlers\exception.py", line 55, in inner
    response = get_response(request)
  File "C:\Users\kongata.AMERIDUKA.000\Desktop\finance-tracker\backend\venv\Lib\site-packages\django\core\handlers\base.py", line 197, in _get_response
    response = wrapped_callback(request, *callback_args, **callback_kwargs)
  File "C:\Users\kongata.AMERIDUKA.000\Desktop\finance-tracker\backend\venv\Lib\site-packages\django\views\decorators\csrf.py", line 65, in _view_wrapper
    return view_func(request, *args, **kwargs)
  File "C:\Users\kongata.AMERIDUKA.000\Desktop\finance-tracker\backend\venv\Lib\site-packages\django\views\generic\base.py", line 105, in view
    return self.dispatch(request, *args, **kwargs)
           ~~~~~~~~~~~~~^^^^^^^^^^^^^^^^^^^^^^^^^^
  File "C:\Users\kongata.AMERIDUKA.000\Desktop\finance-tracker\backend\venv\Lib\site-packages\rest_framework\views.py", line 515, in dispatch
    response = self.handle_exception(exc)
  File "C:\Users\kongata.AMERIDUKA.000\Desktop\finance-tracker\backend\venv\Lib\site-packages\rest_framework\views.py", line 475, in handle_exception
    self.raise_uncaught_exception(exc)
    ~~~~~~~~~~~~~~~~~~~~~~~~~~~~~^^^^^
  File "C:\Users\kongata.AMERIDUKA.000\Desktop\finance-tracker\backend\venv\Lib\site-packages\rest_framework\views.py", line 486, in raise_uncaught_exception
    raise exc
  File "C:\Users\kongata.AMERIDUKA.000\Desktop\finance-tracker\backend\venv\Lib\site-packages\rest_framework\views.py", line 512, in dispatch
    response = handler(request, *args, **kwargs)
  File "C:\Users\kongata.AMERIDUKA.000\Desktop\finance-tracker\backend\dashboard\views.py", line 81, in get
    } for e in recent_expenses
               ^^^^^^^^^^^^^^^
  File "C:\Users\kongata.AMERIDUKA.000\Desktop\finance-tracker\backend\venv\Lib\site-packages\django\db\models\query.py", line 384, in __iter__
    self._fetch_all()
    ~~~~~~~~~~~~~~~^^
  File "C:\Users\kongata.AMERIDUKA.000\Desktop\finance-tracker\backend\venv\Lib\site-packages\django\db\models\query.py", line 1949, in _fetch_all
    self._result_cache = list(self._iterable_class(self))
                         ~~~~^^^^^^^^^^^^^^^^^^^^^^^^^^^^
  File "C:\Users\kongata.AMERIDUKA.000\Desktop\finance-tracker\backend\venv\Lib\site-packages\django\db\models\query.py", line 91, in __iter__
    results = compiler.execute_sql(
        chunked_fetch=self.chunked_fetch, chunk_size=self.chunk_size
    )
  File "C:\Users\kongata.AMERIDUKA.000\Desktop\finance-tracker\backend\venv\Lib\site-packages\django\db\models\sql\compiler.py", line 1623, in execute_sql
    cursor.execute(sql, params)
    ~~~~~~~~~~~~~~^^^^^^^^^^^^^
  File "C:\Users\kongata.AMERIDUKA.000\Desktop\finance-tracker\backend\venv\Lib\site-packages\django\db\backends\utils.py", line 122, in execute
    return super().execute(sql, params)
           ~~~~~~~~~~~~~~~^^^^^^^^^^^^^
  File "C:\Users\kongata.AMERIDUKA.000\Desktop\finance-tracker\backend\venv\Lib\site-packages\django\db\backends\utils.py", line 79, in execute
    return self._execute_with_wrappers(
           ~~~~~~~~~~~~~~~~~~~~~~~~~~~^
        sql, params, many=False, executor=self._execute
        ^^^^^^^^^^^^^^^^^^^^^^^^^^^^^^^^^^^^^^^^^^^^^^^
    )
    ^
  File "C:\Users\kongata.AMERIDUKA.000\Desktop\finance-tracker\backend\venv\Lib\site-packages\django\db\backends\utils.py", line 92, in _execute_with_wrappers
    return executor(sql, params, many, context)
  File "C:\Users\kongata.AMERIDUKA.000\Desktop\finance-tracker\backend\venv\Lib\site-packages\django\db\backends\utils.py", line 100, in _execute
    with self.db.wrap_database_errors:
         ^^^^^^^^^^^^^^^^^^^^^^^^^^^^
  File "C:\Users\kongata.AMERIDUKA.000\Desktop\finance-tracker\backend\venv\Lib\site-packages\django\db\utils.py", line 91, in __exit__
    raise dj_exc_value.with_traceback(traceback) from exc_value
  File "C:\Users\kongata.AMERIDUKA.000\Desktop\finance-tracker\backend\venv\Lib\site-packages\django\db\backends\utils.py", line 105, in _execute
    return self.cursor.execute(sql, params)
           ~~~~~~~~~~~~~~~~~~~^^^^^^^^^^^^^
  File "C:\Users\kongata.AMERIDUKA.000\Desktop\finance-tracker\backend\venv\Lib\site-packages\django\db\backends\sqlite3\base.py", line 360, in execute
    return super().execute(query, params)
           ~~~~~~~~~~~~~~~^^^^^^^^^^^^^^^
django.db.utils.OperationalError: no such column: expense_expense.category_fk_id
ERROR 2025-08-12 04:45:08,043 basehttp 70024 29484 "GET /api/dashboard/ HTTP/1.1" 500 169001
ERROR 2025-08-12 04:49:45,096 log 70024 29484 Internal Server Error: /api/dashboard/
Traceback (most recent call last):
  File "C:\Users\kongata.AMERIDUKA.000\Desktop\finance-tracker\backend\venv\Lib\site-packages\django\db\backends\utils.py", line 105, in _execute
    return self.cursor.execute(sql, params)
           ~~~~~~~~~~~~~~~~~~~^^^^^^^^^^^^^
  File "C:\Users\kongata.AMERIDUKA.000\Desktop\finance-tracker\backend\venv\Lib\site-packages\django\db\backends\sqlite3\base.py", line 360, in execute
    return super().execute(query, params)
           ~~~~~~~~~~~~~~~^^^^^^^^^^^^^^^
sqlite3.OperationalError: no such column: expense_expense.category_fk_id

The above exception was the direct cause of the following exception:

Traceback (most recent call last):
  File "C:\Users\kongata.AMERIDUKA.000\Desktop\finance-tracker\backend\venv\Lib\site-packages\django\core\handlers\exception.py", line 55, in inner
    response = get_response(request)
  File "C:\Users\kongata.AMERIDUKA.000\Desktop\finance-tracker\backend\venv\Lib\site-packages\django\core\handlers\base.py", line 197, in _get_response
    response = wrapped_callback(request, *callback_args, **callback_kwargs)
  File "C:\Users\kongata.AMERIDUKA.000\Desktop\finance-tracker\backend\venv\Lib\site-packages\django\views\decorators\csrf.py", line 65, in _view_wrapper
    return view_func(request, *args, **kwargs)
  File "C:\Users\kongata.AMERIDUKA.000\Desktop\finance-tracker\backend\venv\Lib\site-packages\django\views\generic\base.py", line 105, in view
    return self.dispatch(request, *args, **kwargs)
           ~~~~~~~~~~~~~^^^^^^^^^^^^^^^^^^^^^^^^^^
  File "C:\Users\kongata.AMERIDUKA.000\Desktop\finance-tracker\backend\venv\Lib\site-packages\rest_framework\views.py", line 515, in dispatch
    response = self.handle_exception(exc)
  File "C:\Users\kongata.AMERIDUKA.000\Desktop\finance-tracker\backend\venv\Lib\site-packages\rest_framework\views.py", line 475, in handle_exception
    self.raise_uncaught_exception(exc)
    ~~~~~~~~~~~~~~~~~~~~~~~~~~~~~^^^^^
  File "C:\Users\kongata.AMERIDUKA.000\Desktop\finance-tracker\backend\venv\Lib\site-packages\rest_framework\views.py", line 486, in raise_uncaught_exception
    raise exc
  File "C:\Users\kongata.AMERIDUKA.000\Desktop\finance-tracker\backend\venv\Lib\site-packages\rest_framework\views.py", line 512, in dispatch
    response = handler(request, *args, **kwargs)
  File "C:\Users\kongata.AMERIDUKA.000\Desktop\finance-tracker\backend\dashboard\views.py", line 81, in get
    } for e in recent_expenses
               ^^^^^^^^^^^^^^^
  File "C:\Users\kongata.AMERIDUKA.000\Desktop\finance-tracker\backend\venv\Lib\site-packages\django\db\models\query.py", line 384, in __iter__
    self._fetch_all()
    ~~~~~~~~~~~~~~~^^
  File "C:\Users\kongata.AMERIDUKA.000\Desktop\finance-tracker\backend\venv\Lib\site-packages\django\db\models\query.py", line 1949, in _fetch_all
    self._result_cache = list(self._iterable_class(self))
                         ~~~~^^^^^^^^^^^^^^^^^^^^^^^^^^^^
  File "C:\Users\kongata.AMERIDUKA.000\Desktop\finance-tracker\backend\venv\Lib\site-packages\django\db\models\query.py", line 91, in __iter__
    results = compiler.execute_sql(
        chunked_fetch=self.chunked_fetch, chunk_size=self.chunk_size
    )
  File "C:\Users\kongata.AMERIDUKA.000\Desktop\finance-tracker\backend\venv\Lib\site-packages\django\db\models\sql\compiler.py", line 1623, in execute_sql
    cursor.execute(sql, params)
    ~~~~~~~~~~~~~~^^^^^^^^^^^^^
  File "C:\Users\kongata.AMERIDUKA.000\Desktop\finance-tracker\backend\venv\Lib\site-packages\django\db\backends\utils.py", line 122, in execute
    return super().execute(sql, params)
           ~~~~~~~~~~~~~~~^^^^^^^^^^^^^
  File "C:\Users\kongata.AMERIDUKA.000\Desktop\finance-tracker\backend\venv\Lib\site-packages\django\db\backends\utils.py", line 79, in execute
    return self._execute_with_wrappers(
           ~~~~~~~~~~~~~~~~~~~~~~~~~~~^
        sql, params, many=False, executor=self._execute
        ^^^^^^^^^^^^^^^^^^^^^^^^^^^^^^^^^^^^^^^^^^^^^^^
    )
    ^
  File "C:\Users\kongata.AMERIDUKA.000\Desktop\finance-tracker\backend\venv\Lib\site-packages\django\db\backends\utils.py", line 92, in _execute_with_wrappers
    return executor(sql, params, many, context)
  File "C:\Users\kongata.AMERIDUKA.000\Desktop\finance-tracker\backend\venv\Lib\site-packages\django\db\backends\utils.py", line 100, in _execute
    with self.db.wrap_database_errors:
         ^^^^^^^^^^^^^^^^^^^^^^^^^^^^
  File "C:\Users\kongata.AMERIDUKA.000\Desktop\finance-tracker\backend\venv\Lib\site-packages\django\db\utils.py", line 91, in __exit__
    raise dj_exc_value.with_traceback(traceback) from exc_value
  File "C:\Users\kongata.AMERIDUKA.000\Desktop\finance-tracker\backend\venv\Lib\site-packages\django\db\backends\utils.py", line 105, in _execute
    return self.cursor.execute(sql, params)
           ~~~~~~~~~~~~~~~~~~~^^^^^^^^^^^^^
  File "C:\Users\kongata.AMERIDUKA.000\Desktop\finance-tracker\backend\venv\Lib\site-packages\django\db\backends\sqlite3\base.py", line 360, in execute
    return super().execute(query, params)
           ~~~~~~~~~~~~~~~^^^^^^^^^^^^^^^
django.db.utils.OperationalError: no such column: expense_expense.category_fk_id
ERROR 2025-08-12 04:49:45,099 basehttp 70024 29484 "GET /api/dashboard/ HTTP/1.1" 500 169001
ERROR 2025-08-12 04:49:45,146 log 70024 72576 Internal Server Error: /api/dashboard/
Traceback (most recent call last):
  File "C:\Users\kongata.AMERIDUKA.000\Desktop\finance-tracker\backend\venv\Lib\site-packages\django\db\backends\utils.py", line 105, in _execute
    return self.cursor.execute(sql, params)
           ~~~~~~~~~~~~~~~~~~~^^^^^^^^^^^^^
  File "C:\Users\kongata.AMERIDUKA.000\Desktop\finance-tracker\backend\venv\Lib\site-packages\django\db\backends\sqlite3\base.py", line 360, in execute
    return super().execute(query, params)
           ~~~~~~~~~~~~~~~^^^^^^^^^^^^^^^
sqlite3.OperationalError: no such column: expense_expense.category_fk_id

The above exception was the direct cause of the following exception:

Traceback (most recent call last):
  File "C:\Users\kongata.AMERIDUKA.000\Desktop\finance-tracker\backend\venv\Lib\site-packages\django\core\handlers\exception.py", line 55, in inner
    response = get_response(request)
  File "C:\Users\kongata.AMERIDUKA.000\Desktop\finance-tracker\backend\venv\Lib\site-packages\django\core\handlers\base.py", line 197, in _get_response
    response = wrapped_callback(request, *callback_args, **callback_kwargs)
  File "C:\Users\kongata.AMERIDUKA.000\Desktop\finance-tracker\backend\venv\Lib\site-packages\django\views\decorators\csrf.py", line 65, in _view_wrapper
    return view_func(request, *args, **kwargs)
  File "C:\Users\kongata.AMERIDUKA.000\Desktop\finance-tracker\backend\venv\Lib\site-packages\django\views\generic\base.py", line 105, in view
    return self.dispatch(request, *args, **kwargs)
           ~~~~~~~~~~~~~^^^^^^^^^^^^^^^^^^^^^^^^^^
  File "C:\Users\kongata.AMERIDUKA.000\Desktop\finance-tracker\backend\venv\Lib\site-packages\rest_framework\views.py", line 515, in dispatch
    response = self.handle_exception(exc)
  File "C:\Users\kongata.AMERIDUKA.000\Desktop\finance-tracker\backend\venv\Lib\site-packages\rest_framework\views.py", line 475, in handle_exception
    self.raise_uncaught_exception(exc)
    ~~~~~~~~~~~~~~~~~~~~~~~~~~~~~^^^^^
  File "C:\Users\kongata.AMERIDUKA.000\Desktop\finance-tracker\backend\venv\Lib\site-packages\rest_framework\views.py", line 486, in raise_uncaught_exception
    raise exc
  File "C:\Users\kongata.AMERIDUKA.000\Desktop\finance-tracker\backend\venv\Lib\site-packages\rest_framework\views.py", line 512, in dispatch
    response = handler(request, *args, **kwargs)
  File "C:\Users\kongata.AMERIDUKA.000\Desktop\finance-tracker\backend\dashboard\views.py", line 81, in get
    } for e in recent_expenses
               ^^^^^^^^^^^^^^^
  File "C:\Users\kongata.AMERIDUKA.000\Desktop\finance-tracker\backend\venv\Lib\site-packages\django\db\models\query.py", line 384, in __iter__
    self._fetch_all()
    ~~~~~~~~~~~~~~~^^
  File "C:\Users\kongata.AMERIDUKA.000\Desktop\finance-tracker\backend\venv\Lib\site-packages\django\db\models\query.py", line 1949, in _fetch_all
    self._result_cache = list(self._iterable_class(self))
                         ~~~~^^^^^^^^^^^^^^^^^^^^^^^^^^^^
  File "C:\Users\kongata.AMERIDUKA.000\Desktop\finance-tracker\backend\venv\Lib\site-packages\django\db\models\query.py", line 91, in __iter__
    results = compiler.execute_sql(
        chunked_fetch=self.chunked_fetch, chunk_size=self.chunk_size
    )
  File "C:\Users\kongata.AMERIDUKA.000\Desktop\finance-tracker\backend\venv\Lib\site-packages\django\db\models\sql\compiler.py", line 1623, in execute_sql
    cursor.execute(sql, params)
    ~~~~~~~~~~~~~~^^^^^^^^^^^^^
  File "C:\Users\kongata.AMERIDUKA.000\Desktop\finance-tracker\backend\venv\Lib\site-packages\django\db\backends\utils.py", line 122, in execute
    return super().execute(sql, params)
           ~~~~~~~~~~~~~~~^^^^^^^^^^^^^
  File "C:\Users\kongata.AMERIDUKA.000\Desktop\finance-tracker\backend\venv\Lib\site-packages\django\db\backends\utils.py", line 79, in execute
    return self._execute_with_wrappers(
           ~~~~~~~~~~~~~~~~~~~~~~~~~~~^
        sql, params, many=False, executor=self._execute
        ^^^^^^^^^^^^^^^^^^^^^^^^^^^^^^^^^^^^^^^^^^^^^^^
    )
    ^
  File "C:\Users\kongata.AMERIDUKA.000\Desktop\finance-tracker\backend\venv\Lib\site-packages\django\db\backends\utils.py", line 92, in _execute_with_wrappers
    return executor(sql, params, many, context)
  File "C:\Users\kongata.AMERIDUKA.000\Desktop\finance-tracker\backend\venv\Lib\site-packages\django\db\backends\utils.py", line 100, in _execute
    with self.db.wrap_database_errors:
         ^^^^^^^^^^^^^^^^^^^^^^^^^^^^
  File "C:\Users\kongata.AMERIDUKA.000\Desktop\finance-tracker\backend\venv\Lib\site-packages\django\db\utils.py", line 91, in __exit__
    raise dj_exc_value.with_traceback(traceback) from exc_value
  File "C:\Users\kongata.AMERIDUKA.000\Desktop\finance-tracker\backend\venv\Lib\site-packages\django\db\backends\utils.py", line 105, in _execute
    return self.cursor.execute(sql, params)
           ~~~~~~~~~~~~~~~~~~~^^^^^^^^^^^^^
  File "C:\Users\kongata.AMERIDUKA.000\Desktop\finance-tracker\backend\venv\Lib\site-packages\django\db\backends\sqlite3\base.py", line 360, in execute
    return super().execute(query, params)
           ~~~~~~~~~~~~~~~^^^^^^^^^^^^^^^
django.db.utils.OperationalError: no such column: expense_expense.category_fk_id
ERROR 2025-08-12 04:49:45,149 basehttp 70024 72576 "GET /api/dashboard/ HTTP/1.1" 500 169001
ERROR 2025-08-12 04:50:21,244 log 70024 70432 Internal Server Error: /api/dashboard/
Traceback (most recent call last):
  File "C:\Users\kongata.AMERIDUKA.000\Desktop\finance-tracker\backend\venv\Lib\site-packages\django\db\backends\utils.py", line 105, in _execute
    return self.cursor.execute(sql, params)
           ~~~~~~~~~~~~~~~~~~~^^^^^^^^^^^^^
  File "C:\Users\kongata.AMERIDUKA.000\Desktop\finance-tracker\backend\venv\Lib\site-packages\django\db\backends\sqlite3\base.py", line 360, in execute
    return super().execute(query, params)
           ~~~~~~~~~~~~~~~^^^^^^^^^^^^^^^
sqlite3.OperationalError: no such column: expense_expense.category_fk_id

The above exception was the direct cause of the following exception:

Traceback (most recent call last):
  File "C:\Users\kongata.AMERIDUKA.000\Desktop\finance-tracker\backend\venv\Lib\site-packages\django\core\handlers\exception.py", line 55, in inner
    response = get_response(request)
  File "C:\Users\kongata.AMERIDUKA.000\Desktop\finance-tracker\backend\venv\Lib\site-packages\django\core\handlers\base.py", line 197, in _get_response
    response = wrapped_callback(request, *callback_args, **callback_kwargs)
  File "C:\Users\kongata.AMERIDUKA.000\Desktop\finance-tracker\backend\venv\Lib\site-packages\django\views\decorators\csrf.py", line 65, in _view_wrapper
    return view_func(request, *args, **kwargs)
  File "C:\Users\kongata.AMERIDUKA.000\Desktop\finance-tracker\backend\venv\Lib\site-packages\django\views\generic\base.py", line 105, in view
    return self.dispatch(request, *args, **kwargs)
           ~~~~~~~~~~~~~^^^^^^^^^^^^^^^^^^^^^^^^^^
  File "C:\Users\kongata.AMERIDUKA.000\Desktop\finance-tracker\backend\venv\Lib\site-packages\rest_framework\views.py", line 515, in dispatch
    response = self.handle_exception(exc)
  File "C:\Users\kongata.AMERIDUKA.000\Desktop\finance-tracker\backend\venv\Lib\site-packages\rest_framework\views.py", line 475, in handle_exception
    self.raise_uncaught_exception(exc)
    ~~~~~~~~~~~~~~~~~~~~~~~~~~~~~^^^^^
  File "C:\Users\kongata.AMERIDUKA.000\Desktop\finance-tracker\backend\venv\Lib\site-packages\rest_framework\views.py", line 486, in raise_uncaught_exception
    raise exc
  File "C:\Users\kongata.AMERIDUKA.000\Desktop\finance-tracker\backend\venv\Lib\site-packages\rest_framework\views.py", line 512, in dispatch
    response = handler(request, *args, **kwargs)
  File "C:\Users\kongata.AMERIDUKA.000\Desktop\finance-tracker\backend\dashboard\views.py", line 81, in get
    } for e in recent_expenses
               ^^^^^^^^^^^^^^^
  File "C:\Users\kongata.AMERIDUKA.000\Desktop\finance-tracker\backend\venv\Lib\site-packages\django\db\models\query.py", line 384, in __iter__
    self._fetch_all()
    ~~~~~~~~~~~~~~~^^
  File "C:\Users\kongata.AMERIDUKA.000\Desktop\finance-tracker\backend\venv\Lib\site-packages\django\db\models\query.py", line 1949, in _fetch_all
    self._result_cache = list(self._iterable_class(self))
                         ~~~~^^^^^^^^^^^^^^^^^^^^^^^^^^^^
  File "C:\Users\kongata.AMERIDUKA.000\Desktop\finance-tracker\backend\venv\Lib\site-packages\django\db\models\query.py", line 91, in __iter__
    results = compiler.execute_sql(
        chunked_fetch=self.chunked_fetch, chunk_size=self.chunk_size
    )
  File "C:\Users\kongata.AMERIDUKA.000\Desktop\finance-tracker\backend\venv\Lib\site-packages\django\db\models\sql\compiler.py", line 1623, in execute_sql
    cursor.execute(sql, params)
    ~~~~~~~~~~~~~~^^^^^^^^^^^^^
  File "C:\Users\kongata.AMERIDUKA.000\Desktop\finance-tracker\backend\venv\Lib\site-packages\django\db\backends\utils.py", line 122, in execute
    return super().execute(sql, params)
           ~~~~~~~~~~~~~~~^^^^^^^^^^^^^
  File "C:\Users\kongata.AMERIDUKA.000\Desktop\finance-tracker\backend\venv\Lib\site-packages\django\db\backends\utils.py", line 79, in execute
    return self._execute_with_wrappers(
           ~~~~~~~~~~~~~~~~~~~~~~~~~~~^
        sql, params, many=False, executor=self._execute
        ^^^^^^^^^^^^^^^^^^^^^^^^^^^^^^^^^^^^^^^^^^^^^^^
    )
    ^
  File "C:\Users\kongata.AMERIDUKA.000\Desktop\finance-tracker\backend\venv\Lib\site-packages\django\db\backends\utils.py", line 92, in _execute_with_wrappers
    return executor(sql, params, many, context)
  File "C:\Users\kongata.AMERIDUKA.000\Desktop\finance-tracker\backend\venv\Lib\site-packages\django\db\backends\utils.py", line 100, in _execute
    with self.db.wrap_database_errors:
         ^^^^^^^^^^^^^^^^^^^^^^^^^^^^
  File "C:\Users\kongata.AMERIDUKA.000\Desktop\finance-tracker\backend\venv\Lib\site-packages\django\db\utils.py", line 91, in __exit__
    raise dj_exc_value.with_traceback(traceback) from exc_value
  File "C:\Users\kongata.AMERIDUKA.000\Desktop\finance-tracker\backend\venv\Lib\site-packages\django\db\backends\utils.py", line 105, in _execute
    return self.cursor.execute(sql, params)
           ~~~~~~~~~~~~~~~~~~~^^^^^^^^^^^^^
  File "C:\Users\kongata.AMERIDUKA.000\Desktop\finance-tracker\backend\venv\Lib\site-packages\django\db\backends\sqlite3\base.py", line 360, in execute
    return super().execute(query, params)
           ~~~~~~~~~~~~~~~^^^^^^^^^^^^^^^
django.db.utils.OperationalError: no such column: expense_expense.category_fk_id
ERROR 2025-08-12 04:50:21,247 basehttp 70024 70432 "GET /api/dashboard/ HTTP/1.1" 500 169001
ERROR 2025-08-12 04:50:21,297 log 70024 29484 Internal Server Error: /api/dashboard/
Traceback (most recent call last):
  File "C:\Users\kongata.AMERIDUKA.000\Desktop\finance-tracker\backend\venv\Lib\site-packages\django\db\backends\utils.py", line 105, in _execute
    return self.cursor.execute(sql, params)
           ~~~~~~~~~~~~~~~~~~~^^^^^^^^^^^^^
  File "C:\Users\kongata.AMERIDUKA.000\Desktop\finance-tracker\backend\venv\Lib\site-packages\django\db\backends\sqlite3\base.py", line 360, in execute
    return super().execute(query, params)
           ~~~~~~~~~~~~~~~^^^^^^^^^^^^^^^
sqlite3.OperationalError: no such column: expense_expense.category_fk_id

The above exception was the direct cause of the following exception:

Traceback (most recent call last):
  File "C:\Users\kongata.AMERIDUKA.000\Desktop\finance-tracker\backend\venv\Lib\site-packages\django\core\handlers\exception.py", line 55, in inner
    response = get_response(request)
  File "C:\Users\kongata.AMERIDUKA.000\Desktop\finance-tracker\backend\venv\Lib\site-packages\django\core\handlers\base.py", line 197, in _get_response
    response = wrapped_callback(request, *callback_args, **callback_kwargs)
  File "C:\Users\kongata.AMERIDUKA.000\Desktop\finance-tracker\backend\venv\Lib\site-packages\django\views\decorators\csrf.py", line 65, in _view_wrapper
    return view_func(request, *args, **kwargs)
  File "C:\Users\kongata.AMERIDUKA.000\Desktop\finance-tracker\backend\venv\Lib\site-packages\django\views\generic\base.py", line 105, in view
    return self.dispatch(request, *args, **kwargs)
           ~~~~~~~~~~~~~^^^^^^^^^^^^^^^^^^^^^^^^^^
  File "C:\Users\kongata.AMERIDUKA.000\Desktop\finance-tracker\backend\venv\Lib\site-packages\rest_framework\views.py", line 515, in dispatch
    response = self.handle_exception(exc)
  File "C:\Users\kongata.AMERIDUKA.000\Desktop\finance-tracker\backend\venv\Lib\site-packages\rest_framework\views.py", line 475, in handle_exception
    self.raise_uncaught_exception(exc)
    ~~~~~~~~~~~~~~~~~~~~~~~~~~~~~^^^^^
  File "C:\Users\kongata.AMERIDUKA.000\Desktop\finance-tracker\backend\venv\Lib\site-packages\rest_framework\views.py", line 486, in raise_uncaught_exception
    raise exc
  File "C:\Users\kongata.AMERIDUKA.000\Desktop\finance-tracker\backend\venv\Lib\site-packages\rest_framework\views.py", line 512, in dispatch
    response = handler(request, *args, **kwargs)
  File "C:\Users\kongata.AMERIDUKA.000\Desktop\finance-tracker\backend\dashboard\views.py", line 81, in get
    } for e in recent_expenses
               ^^^^^^^^^^^^^^^
  File "C:\Users\kongata.AMERIDUKA.000\Desktop\finance-tracker\backend\venv\Lib\site-packages\django\db\models\query.py", line 384, in __iter__
    self._fetch_all()
    ~~~~~~~~~~~~~~~^^
  File "C:\Users\kongata.AMERIDUKA.000\Desktop\finance-tracker\backend\venv\Lib\site-packages\django\db\models\query.py", line 1949, in _fetch_all
    self._result_cache = list(self._iterable_class(self))
                         ~~~~^^^^^^^^^^^^^^^^^^^^^^^^^^^^
  File "C:\Users\kongata.AMERIDUKA.000\Desktop\finance-tracker\backend\venv\Lib\site-packages\django\db\models\query.py", line 91, in __iter__
    results = compiler.execute_sql(
        chunked_fetch=self.chunked_fetch, chunk_size=self.chunk_size
    )
  File "C:\Users\kongata.AMERIDUKA.000\Desktop\finance-tracker\backend\venv\Lib\site-packages\django\db\models\sql\compiler.py", line 1623, in execute_sql
    cursor.execute(sql, params)
    ~~~~~~~~~~~~~~^^^^^^^^^^^^^
  File "C:\Users\kongata.AMERIDUKA.000\Desktop\finance-tracker\backend\venv\Lib\site-packages\django\db\backends\utils.py", line 122, in execute
    return super().execute(sql, params)
           ~~~~~~~~~~~~~~~^^^^^^^^^^^^^
  File "C:\Users\kongata.AMERIDUKA.000\Desktop\finance-tracker\backend\venv\Lib\site-packages\django\db\backends\utils.py", line 79, in execute
    return self._execute_with_wrappers(
           ~~~~~~~~~~~~~~~~~~~~~~~~~~~^
        sql, params, many=False, executor=self._execute
        ^^^^^^^^^^^^^^^^^^^^^^^^^^^^^^^^^^^^^^^^^^^^^^^
    )
    ^
  File "C:\Users\kongata.AMERIDUKA.000\Desktop\finance-tracker\backend\venv\Lib\site-packages\django\db\backends\utils.py", line 92, in _execute_with_wrappers
    return executor(sql, params, many, context)
  File "C:\Users\kongata.AMERIDUKA.000\Desktop\finance-tracker\backend\venv\Lib\site-packages\django\db\backends\utils.py", line 100, in _execute
    with self.db.wrap_database_errors:
         ^^^^^^^^^^^^^^^^^^^^^^^^^^^^
  File "C:\Users\kongata.AMERIDUKA.000\Desktop\finance-tracker\backend\venv\Lib\site-packages\django\db\utils.py", line 91, in __exit__
    raise dj_exc_value.with_traceback(traceback) from exc_value
  File "C:\Users\kongata.AMERIDUKA.000\Desktop\finance-tracker\backend\venv\Lib\site-packages\django\db\backends\utils.py", line 105, in _execute
    return self.cursor.execute(sql, params)
           ~~~~~~~~~~~~~~~~~~~^^^^^^^^^^^^^
  File "C:\Users\kongata.AMERIDUKA.000\Desktop\finance-tracker\backend\venv\Lib\site-packages\django\db\backends\sqlite3\base.py", line 360, in execute
    return super().execute(query, params)
           ~~~~~~~~~~~~~~~^^^^^^^^^^^^^^^
django.db.utils.OperationalError: no such column: expense_expense.category_fk_id
ERROR 2025-08-12 04:50:21,301 basehttp 70024 29484 "GET /api/dashboard/ HTTP/1.1" 500 169001
